Workbook

Sheet Thành viên
A1: THÔNG TIN THÀNH VIÊN – ĐỒ ÁN IT ONSITE
A3: Mã | B3: Họ và tên | C3: MSSV | D3: Vai trò | E3: Phụ trách chính
A4: TV1 | B4: Phạm Ngọc Trung | C4: 080205000925 | D4: Trưởng nhóm | E4: Backend, AI, triển khai
A5: TV2 | B5: Trần Quốc Anh Hoàng | D5: Thành viên | E5: Frontend, giao diện
A6: TV3 | B6: Nguyễn Văn Thu | D6: Thành viên | E6: Phân tích nghiệp vụ, kiểm thử, tài liệu

Sheet Tiến độ
A1: TIẾN ĐỘ ĐỒ ÁN – IT ONSITE
A3: Hoàn thành toàn dự án | B3: =G13 -> 0
A5: THEO GIAI ĐOẠN
A6: Giai đoạn | B6: Số công việc | C6: Đã làm | D6: Đang làm | E6: Chưa làm | F6: Quá hạn | G6: % hoàn thành
A7: GĐ1 – Quản lý dự án | B7: =COUNTIFS('GĐ1 Quản lý dự án'!$H$5:$H$300,"TV*") -> 6 | C7: =COUNTIFS('GĐ1 Quản lý dự án'!$H$5:$H$300,"TV*",'GĐ1 Quản lý dự án'!$N$5:$N$300,"Đã làm") -> 0 | D7: =COUNTIFS('GĐ1 Quản lý dự án'!$H$5:$H$300,"TV*",'GĐ1 Quản lý dự án'!$N$5:$N$300,"Đang làm") -> 0 | E7: =COUNTIFS('GĐ1 Quản lý dự án'!$H$5:$H$300,"TV*",'GĐ1 Quản lý dự án'!$N$5:$N$300,"Chưa làm") -> 6 | F7: =COUNTIFS('GĐ1 Quản lý dự án'!$H$5:$H$300,"TV*",'GĐ1 Quản lý dự án'!$M$5:$M$300,"<"&TODAY(),'GĐ1 Quản lý dự án'!$N$5:$N$300,"<>Đã làm") -> 0 | G7: =IF(B7=0,0,C7/B7) -> 0
A8: GĐ2 – Phân tích yêu cầu | B8: =COUNTIFS('GĐ2 Phân tích yêu cầu'!$H$5:$H$300,"TV*") -> 9 | C8: =COUNTIFS('GĐ2 Phân tích yêu cầu'!$H$5:$H$300,"TV*",'GĐ2 Phân tích yêu cầu'!$N$5:$N$300,"Đã làm") -> 0 | D8: =COUNTIFS('GĐ2 Phân tích yêu cầu'!$H$5:$H$300,"TV*",'GĐ2 Phân tích yêu cầu'!$N$5:$N$300,"Đang làm") -> 0 | E8: =COUNTIFS('GĐ2 Phân tích yêu cầu'!$H$5:$H$300,"TV*",'GĐ2 Phân tích yêu cầu'!$N$5:$N$300,"Chưa làm") -> 9 | F8: =COUNTIFS('GĐ2 Phân tích yêu cầu'!$H$5:$H$300,"TV*",'GĐ2 Phân tích yêu cầu'!$M$5:$M$300,"<"&TODAY(),'GĐ2 Phân tích yêu cầu'!$N$5:$N$300,"<>Đã làm") -> 0 | G8: =IF(B8=0,0,C8/B8) -> 0
A9: GĐ3 – Thiết kế | B9: =COUNTIFS('GĐ3 Thiết kế'!$H$5:$H$300,"TV*") -> 11 | C9: =COUNTIFS('GĐ3 Thiết kế'!$H$5:$H$300,"TV*",'GĐ3 Thiết kế'!$N$5:$N$300,"Đã làm") -> 0 | D9: =COUNTIFS('GĐ3 Thiết kế'!$H$5:$H$300,"TV*",'GĐ3 Thiết kế'!$N$5:$N$300,"Đang làm") -> 0 | E9: =COUNTIFS('GĐ3 Thiết kế'!$H$5:$H$300,"TV*",'GĐ3 Thiết kế'!$N$5:$N$300,"Chưa làm") -> 11 | F9: =COUNTIFS('GĐ3 Thiết kế'!$H$5:$H$300,"TV*",'GĐ3 Thiết kế'!$M$5:$M$300,"<"&TODAY(),'GĐ3 Thiết kế'!$N$5:$N$300,"<>Đã làm") -> 0 | G9: =IF(B9=0,0,C9/B9) -> 0
A10: GĐ4 – Lập trình | B10: =COUNTIFS('GĐ4 Lập trình'!$H$5:$H$300,"TV*") -> 17 | C10: =COUNTIFS('GĐ4 Lập trình'!$H$5:$H$300,"TV*",'GĐ4 Lập trình'!$N$5:$N$300,"Đã làm") -> 0 | D10: =COUNTIFS('GĐ4 Lập trình'!$H$5:$H$300,"TV*",'GĐ4 Lập trình'!$N$5:$N$300,"Đang làm") -> 0 | E10: =COUNTIFS('GĐ4 Lập trình'!$H$5:$H$300,"TV*",'GĐ4 Lập trình'!$N$5:$N$300,"Chưa làm") -> 17 | F10: =COUNTIFS('GĐ4 Lập trình'!$H$5:$H$300,"TV*",'GĐ4 Lập trình'!$M$5:$M$300,"<"&TODAY(),'GĐ4 Lập trình'!$N$5:$N$300,"<>Đã làm") -> 0 | G10: =IF(B10=0,0,C10/B10) -> 0
A11: GĐ5 – Kiểm thử | B11: =COUNTIFS('GĐ5 Kiểm thử'!$H$5:$H$300,"TV*") -> 7 | C11: =COUNTIFS('GĐ5 Kiểm thử'!$H$5:$H$300,"TV*",'GĐ5 Kiểm thử'!$N$5:$N$300,"Đã làm") -> 0 | D11: =COUNTIFS('GĐ5 Kiểm thử'!$H$5:$H$300,"TV*",'GĐ5 Kiểm thử'!$N$5:$N$300,"Đang làm") -> 0 | E11: =COUNTIFS('GĐ5 Kiểm thử'!$H$5:$H$300,"TV*",'GĐ5 Kiểm thử'!$N$5:$N$300,"Chưa làm") -> 7 | F11: =COUNTIFS('GĐ5 Kiểm thử'!$H$5:$H$300,"TV*",'GĐ5 Kiểm thử'!$M$5:$M$300,"<"&TODAY(),'GĐ5 Kiểm thử'!$N$5:$N$300,"<>Đã làm") -> 0 | G11: =IF(B11=0,0,C11/B11) -> 0
A12: GĐ6 – Triển khai và bảo vệ | B12: =COUNTIFS('GĐ6 Triển khai và bảo vệ'!$H$5:$H$300,"TV*") -> 7 | C12: =COUNTIFS('GĐ6 Triển khai và bảo vệ'!$H$5:$H$300,"TV*",'GĐ6 Triển khai và bảo vệ'!$N$5:$N$300,"Đã làm") -> 0 | D12: =COUNTIFS('GĐ6 Triển khai và bảo vệ'!$H$5:$H$300,"TV*",'GĐ6 Triển khai và bảo vệ'!$N$5:$N$300,"Đang làm") -> 0 | E12: =COUNTIFS('GĐ6 Triển khai và bảo vệ'!$H$5:$H$300,"TV*",'GĐ6 Triển khai và bảo vệ'!$N$5:$N$300,"Chưa làm") -> 7 | F12: =COUNTIFS('GĐ6 Triển khai và bảo vệ'!$H$5:$H$300,"TV*",'GĐ6 Triển khai và bảo vệ'!$M$5:$M$300,"<"&TODAY(),'GĐ6 Triển khai và bảo vệ'!$N$5:$N$300,"<>Đã làm") -> 0 | G12: =IF(B12=0,0,C12/B12) -> 0
A13: Tổng | B13: =SUM(B7:B12) -> 57 | C13: =SUM(C7:C12) -> 0 | D13: =SUM(D7:D12) -> 0 | E13: =SUM(E7:E12) -> 57 | F13: =SUM(F7:F12) -> 0 | G13: =IF(B13=0,0,C13/B13) -> 0
A15: THEO THÀNH VIÊN
A16: Thành viên | B16: Số công việc | C16: Đã làm | D16: Đang làm | E16: Chưa làm | F16: Quá hạn | G16: % hoàn thành | H16: Tỷ lệ khối lượng
A17: ="TV1 – "&'Thành viên'!B4 -> TV1 – Phạm Ngọc Trung | B17: =COUNTIFS('GĐ1 Quản lý dự án'!$H$5:$H$300,"TV1")+COUNTIFS('GĐ2 Phân tích yêu cầu'!$H$5:$H$300,"TV1")+COUNTIFS('GĐ3 Thiết kế'!$H$5:$H$300,"TV1")+COUNTIFS('GĐ4 Lập trình'!$H$5:$H$300,"TV1")+COUNTIFS('GĐ5 Kiểm thử'!$H$5:$H$300,"TV1")+COUNTIFS('GĐ6 Triển khai và bảo vệ'!$H$5:$H$300,"TV1") -> 21 | C17: =COUNTIFS('GĐ1 Quản lý dự án'!$H$5:$H$300,"TV1",'GĐ1 Quản lý dự án'!$N$5:$N$300,"Đã làm")+COUNTIFS('GĐ2 Phân tích yêu cầu'!$H$5:$H$300,"TV1",'GĐ2 Phân tích yêu cầu'!$N$5:$N$300,"Đã làm")+COUNTIFS('GĐ3 Thiết kế'!$H$5:$H$300,"TV1",'GĐ3 Thiết kế'!$N$5:$N$300,"Đã làm")+COUNTIFS('GĐ4 Lập trình'!$H$5:$H$300,"TV1",'GĐ4 Lập trình'!$N$5:$N$300,"Đã làm")+COUNTIFS('GĐ5 Kiểm thử'!$H$5:$H$300,"TV1",'GĐ5 Kiểm thử'!$N$5:$N$300,"Đã làm")+COUNTIFS('GĐ6 Triển khai và bảo vệ'!$H$5:$H$300,"TV1",'GĐ6 Triển khai và bảo vệ'!$N$5:$N$300,"Đã làm") -> 0 | D17: =COUNTIFS('GĐ1 Quản lý dự án'!$H$5:$H$300,"TV1",'GĐ1 Quản lý dự án'!$N$5:$N$300,"Đang làm")+COUNTIFS('GĐ2 Phân tích yêu cầu'!$H$5:$H$300,"TV1",'GĐ2 Phân tích yêu cầu'!$N$5:$N$300,"Đang làm")+COUNTIFS('GĐ3 Thiết kế'!$H$5:$H$300,"TV1",'GĐ3 Thiết kế'!$N$5:$N$300,"Đang làm")+COUNTIFS('GĐ4 Lập trình'!$H$5:$H$300,"TV1",'GĐ4 Lập trình'!$N$5:$N$300,"Đang làm")+COUNTIFS('GĐ5 Kiểm thử'!$H$5:$H$300,"TV1",'GĐ5 Kiểm thử'!$N$5:$N$300,"Đang làm")+COUNTIFS('GĐ6 Triển khai và bảo vệ'!$H$5:$H$300,"TV1",'GĐ6 Triển khai và bảo vệ'!$N$5:$N$300,"Đang làm") -> 0 | E17: =COUNTIFS('GĐ1 Quản lý dự án'!$H$5:$H$300,"TV1",'GĐ1 Quản lý dự án'!$N$5:$N$300,"Chưa làm")+COUNTIFS('GĐ2 Phân tích yêu cầu'!$H$5:$H$300,"TV1",'GĐ2 Phân tích yêu cầu'!$N$5:$N$300,"Chưa làm")+COUNTIFS('GĐ3 Thiết kế'!$H$5:$H$300,"TV1",'GĐ3 Thiết kế'!$N$5:$N$300,"Chưa làm")+COUNTIFS('GĐ4 Lập trình'!$H$5:$H$300,"TV1",'GĐ4 Lập trình'!$N$5:$N$300,"Chưa làm")+COUNTIFS('GĐ5 Kiểm thử'!$H$5:$H$300,"TV1",'GĐ5 Kiểm thử'!$N$5:$N$300,"Chưa làm")+COUNTIFS('GĐ6 Triển khai và bảo vệ'!$H$5:$H$300,"TV1",'GĐ6 Triển khai và bảo vệ'!$N$5:$N$300,"Chưa làm") -> 21 | F17: =COUNTIFS('GĐ1 Quản lý dự án'!$H$5:$H$300,"TV1",'GĐ1 Quản lý dự án'!$M$5:$M$300,"<"&TODAY(),'GĐ1 Quản lý dự án'!$N$5:$N$300,"<>Đã làm")+COUNTIFS('GĐ2 Phân tích yêu cầu'!$H$5:$H$300,"TV1",'GĐ2 Phân tích yêu cầu'!$M$5:$M$300,"<"&TODAY(),'GĐ2 Phân tích yêu cầu'!$N$5:$N$300,"<>Đã làm")+COUNTIFS('GĐ3 Thiết kế'!$H$5:$H$300,"TV1",'GĐ3 Thiết kế'!$M$5:$M$300,"<"&TODAY(),'GĐ3 Thiết kế'!$N$5:$N$300,"<>Đã làm")+COUNTIFS('GĐ4 Lập trình'!$H$5:$H$300,"TV1",'GĐ4 Lập trình'!$M$5:$M$300,"<"&TODAY(),'GĐ4 Lập trình'!$N$5:$N$300,"<>Đã làm")+COUNTIFS('GĐ5 Kiểm thử'!$H$5:$H$300,"TV1",'GĐ5 Kiểm thử'!$M$5:$M$300,"<"&TODAY(),'GĐ5 Kiểm thử'!$N$5:$N$300,"<>Đã làm")+COUNTIFS('GĐ6 Triển khai và bảo vệ'!$H$5:$H$300,"TV1",'GĐ6 Triển khai và bảo vệ'!$M$5:$M$300,"<"&TODAY(),'GĐ6 Triển khai và bảo vệ'!$N$5:$N$300,"<>Đã làm") -> 0 | G17: =IF(B17=0,0,C17/B17) -> 0 | H17: =IF($B$13=0,0,B17/$B$13) -> 0.36842105
A18: ="TV2 – "&'Thành viên'!B5 -> TV2 – Trần Quốc Anh Hoàng | B18: =COUNTIFS('GĐ1 Quản lý dự án'!$H$5:$H$300,"TV2")+COUNTIFS('GĐ2 Phân tích yêu cầu'!$H$5:$H$300,"TV2")+COUNTIFS('GĐ3 Thiết kế'!$H$5:$H$300,"TV2")+COUNTIFS('GĐ4 Lập trình'!$H$5:$H$300,"TV2")+COUNTIFS('GĐ5 Kiểm thử'!$H$5:$H$300,"TV2")+COUNTIFS('GĐ6 Triển khai và bảo vệ'!$H$5:$H$300,"TV2") -> 17 | C18: =COUNTIFS('GĐ1 Quản lý dự án'!$H$5:$H$300,"TV2",'GĐ1 Quản lý dự án'!$N$5:$N$300,"Đã làm")+COUNTIFS('GĐ2 Phân tích yêu cầu'!$H$5:$H$300,"TV2",'GĐ2 Phân tích yêu cầu'!$N$5:$N$300,"Đã làm")+COUNTIFS('GĐ3 Thiết kế'!$H$5:$H$300,"TV2",'GĐ3 Thiết kế'!$N$5:$N$300,"Đã làm")+COUNTIFS('GĐ4 Lập trình'!$H$5:$H$300,"TV2",'GĐ4 Lập trình'!$N$5:$N$300,"Đã làm")+COUNTIFS('GĐ5 Kiểm thử'!$H$5:$H$300,"TV2",'GĐ5 Kiểm thử'!$N$5:$N$300,"Đã làm")+COUNTIFS('GĐ6 Triển khai và bảo vệ'!$H$5:$H$300,"TV2",'GĐ6 Triển khai và bảo vệ'!$N$5:$N$300,"Đã làm") -> 0 | D18: =COUNTIFS('GĐ1 Quản lý dự án'!$H$5:$H$300,"TV2",'GĐ1 Quản lý dự án'!$N$5:$N$300,"Đang làm")+COUNTIFS('GĐ2 Phân tích yêu cầu'!$H$5:$H$300,"TV2",'GĐ2 Phân tích yêu cầu'!$N$5:$N$300,"Đang làm")+COUNTIFS('GĐ3 Thiết kế'!$H$5:$H$300,"TV2",'GĐ3 Thiết kế'!$N$5:$N$300,"Đang làm")+COUNTIFS('GĐ4 Lập trình'!$H$5:$H$300,"TV2",'GĐ4 Lập trình'!$N$5:$N$300,"Đang làm")+COUNTIFS('GĐ5 Kiểm thử'!$H$5:$H$300,"TV2",'GĐ5 Kiểm thử'!$N$5:$N$300,"Đang làm")+COUNTIFS('GĐ6 Triển khai và bảo vệ'!$H$5:$H$300,"TV2",'GĐ6 Triển khai và bảo vệ'!$N$5:$N$300,"Đang làm") -> 0 | E18: =COUNTIFS('GĐ1 Quản lý dự án'!$H$5:$H$300,"TV2",'GĐ1 Quản lý dự án'!$N$5:$N$300,"Chưa làm")+COUNTIFS('GĐ2 Phân tích yêu cầu'!$H$5:$H$300,"TV2",'GĐ2 Phân tích yêu cầu'!$N$5:$N$300,"Chưa làm")+COUNTIFS('GĐ3 Thiết kế'!$H$5:$H$300,"TV2",'GĐ3 Thiết kế'!$N$5:$N$300,"Chưa làm")+COUNTIFS('GĐ4 Lập trình'!$H$5:$H$300,"TV2",'GĐ4 Lập trình'!$N$5:$N$300,"Chưa làm")+COUNTIFS('GĐ5 Kiểm thử'!$H$5:$H$300,"TV2",'GĐ5 Kiểm thử'!$N$5:$N$300,"Chưa làm")+COUNTIFS('GĐ6 Triển khai và bảo vệ'!$H$5:$H$300,"TV2",'GĐ6 Triển khai và bảo vệ'!$N$5:$N$300,"Chưa làm") -> 17 | F18: =COUNTIFS('GĐ1 Quản lý dự án'!$H$5:$H$300,"TV2",'GĐ1 Quản lý dự án'!$M$5:$M$300,"<"&TODAY(),'GĐ1 Quản lý dự án'!$N$5:$N$300,"<>Đã làm")+COUNTIFS('GĐ2 Phân tích yêu cầu'!$H$5:$H$300,"TV2",'GĐ2 Phân tích yêu cầu'!$M$5:$M$300,"<"&TODAY(),'GĐ2 Phân tích yêu cầu'!$N$5:$N$300,"<>Đã làm")+COUNTIFS('GĐ3 Thiết kế'!$H$5:$H$300,"TV2",'GĐ3 Thiết kế'!$M$5:$M$300,"<"&TODAY(),'GĐ3 Thiết kế'!$N$5:$N$300,"<>Đã làm")+COUNTIFS('GĐ4 Lập trình'!$H$5:$H$300,"TV2",'GĐ4 Lập trình'!$M$5:$M$300,"<"&TODAY(),'GĐ4 Lập trình'!$N$5:$N$300,"<>Đã làm")+COUNTIFS('GĐ5 Kiểm thử'!$H$5:$H$300,"TV2",'GĐ5 Kiểm thử'!$M$5:$M$300,"<"&TODAY(),'GĐ5 Kiểm thử'!$N$5:$N$300,"<>Đã làm")+COUNTIFS('GĐ6 Triển khai và bảo vệ'!$H$5:$H$300,"TV2",'GĐ6 Triển khai và bảo vệ'!$M$5:$M$300,"<"&TODAY(),'GĐ6 Triển khai và bảo vệ'!$N$5:$N$300,"<>Đã làm") -> 0 | G18: =IF(B18=0,0,C18/B18) -> 0 | H18: =IF($B$13=0,0,B18/$B$13) -> 0.29824561
A19: ="TV3 – "&'Thành viên'!B6 -> TV3 – Nguyễn Văn Thu | B19: =COUNTIFS('GĐ1 Quản lý dự án'!$H$5:$H$300,"TV3")+COUNTIFS('GĐ2 Phân tích yêu cầu'!$H$5:$H$300,"TV3")+COUNTIFS('GĐ3 Thiết kế'!$H$5:$H$300,"TV3")+COUNTIFS('GĐ4 Lập trình'!$H$5:$H$300,"TV3")+COUNTIFS('GĐ5 Kiểm thử'!$H$5:$H$300,"TV3")+COUNTIFS('GĐ6 Triển khai và bảo vệ'!$H$5:$H$300,"TV3") -> 19 | C19: =COUNTIFS('GĐ1 Quản lý dự án'!$H$5:$H$300,"TV3",'GĐ1 Quản lý dự án'!$N$5:$N$300,"Đã làm")+COUNTIFS('GĐ2 Phân tích yêu cầu'!$H$5:$H$300,"TV3",'GĐ2 Phân tích yêu cầu'!$N$5:$N$300,"Đã làm")+COUNTIFS('GĐ3 Thiết kế'!$H$5:$H$300,"TV3",'GĐ3 Thiết kế'!$N$5:$N$300,"Đã làm")+COUNTIFS('GĐ4 Lập trình'!$H$5:$H$300,"TV3",'GĐ4 Lập trình'!$N$5:$N$300,"Đã làm")+COUNTIFS('GĐ5 Kiểm thử'!$H$5:$H$300,"TV3",'GĐ5 Kiểm thử'!$N$5:$N$300,"Đã làm")+COUNTIFS('GĐ6 Triển khai và bảo vệ'!$H$5:$H$300,"TV3",'GĐ6 Triển khai và bảo vệ'!$N$5:$N$300,"Đã làm") -> 0 | D19: =COUNTIFS('GĐ1 Quản lý dự án'!$H$5:$H$300,"TV3",'GĐ1 Quản lý dự án'!$N$5:$N$300,"Đang làm")+COUNTIFS('GĐ2 Phân tích yêu cầu'!$H$5:$H$300,"TV3",'GĐ2 Phân tích yêu cầu'!$N$5:$N$300,"Đang làm")+COUNTIFS('GĐ3 Thiết kế'!$H$5:$H$300,"TV3",'GĐ3 Thiết kế'!$N$5:$N$300,"Đang làm")+COUNTIFS('GĐ4 Lập trình'!$H$5:$H$300,"TV3",'GĐ4 Lập trình'!$N$5:$N$300,"Đang làm")+COUNTIFS('GĐ5 Kiểm thử'!$H$5:$H$300,"TV3",'GĐ5 Kiểm thử'!$N$5:$N$300,"Đang làm")+COUNTIFS('GĐ6 Triển khai và bảo vệ'!$H$5:$H$300,"TV3",'GĐ6 Triển khai và bảo vệ'!$N$5:$N$300,"Đang làm") -> 0 | E19: =COUNTIFS('GĐ1 Quản lý dự án'!$H$5:$H$300,"TV3",'GĐ1 Quản lý dự án'!$N$5:$N$300,"Chưa làm")+COUNTIFS('GĐ2 Phân tích yêu cầu'!$H$5:$H$300,"TV3",'GĐ2 Phân tích yêu cầu'!$N$5:$N$300,"Chưa làm")+COUNTIFS('GĐ3 Thiết kế'!$H$5:$H$300,"TV3",'GĐ3 Thiết kế'!$N$5:$N$300,"Chưa làm")+COUNTIFS('GĐ4 Lập trình'!$H$5:$H$300,"TV3",'GĐ4 Lập trình'!$N$5:$N$300,"Chưa làm")+COUNTIFS('GĐ5 Kiểm thử'!$H$5:$H$300,"TV3",'GĐ5 Kiểm thử'!$N$5:$N$300,"Chưa làm")+COUNTIFS('GĐ6 Triển khai và bảo vệ'!$H$5:$H$300,"TV3",'GĐ6 Triển khai và bảo vệ'!$N$5:$N$300,"Chưa làm") -> 19 | F19: =COUNTIFS('GĐ1 Quản lý dự án'!$H$5:$H$300,"TV3",'GĐ1 Quản lý dự án'!$M$5:$M$300,"<"&TODAY(),'GĐ1 Quản lý dự án'!$N$5:$N$300,"<>Đã làm")+COUNTIFS('GĐ2 Phân tích yêu cầu'!$H$5:$H$300,"TV3",'GĐ2 Phân tích yêu cầu'!$M$5:$M$300,"<"&TODAY(),'GĐ2 Phân tích yêu cầu'!$N$5:$N$300,"<>Đã làm")+COUNTIFS('GĐ3 Thiết kế'!$H$5:$H$300,"TV3",'GĐ3 Thiết kế'!$M$5:$M$300,"<"&TODAY(),'GĐ3 Thiết kế'!$N$5:$N$300,"<>Đã làm")+COUNTIFS('GĐ4 Lập trình'!$H$5:$H$300,"TV3",'GĐ4 Lập trình'!$M$5:$M$300,"<"&TODAY(),'GĐ4 Lập trình'!$N$5:$N$300,"<>Đã làm")+COUNTIFS('GĐ5 Kiểm thử'!$H$5:$H$300,"TV3",'GĐ5 Kiểm thử'!$M$5:$M$300,"<"&TODAY(),'GĐ5 Kiểm thử'!$N$5:$N$300,"<>Đã làm")+COUNTIFS('GĐ6 Triển khai và bảo vệ'!$H$5:$H$300,"TV3",'GĐ6 Triển khai và bảo vệ'!$M$5:$M$300,"<"&TODAY(),'GĐ6 Triển khai và bảo vệ'!$N$5:$N$300,"<>Đã làm") -> 0 | G19: =IF(B19=0,0,C19/B19) -> 0 | H19: =IF($B$13=0,0,B19/$B$13) -> 0.33333333
A21: SỐ CÔNG VIỆC VÀ % HOÀN THÀNH THEO GIAI ĐOẠN
A22: Thành viên | B22: GĐ1 | D22: GĐ2 | F22: GĐ3 | H22: GĐ4 | J22: GĐ5 | L22: GĐ6
B23: Số CV | C23: % xong | D23: Số CV | E23: % xong | F23: Số CV | G23: % xong | H23: Số CV | I23: % xong | J23: Số CV | K23: % xong | L23: Số CV | M23: % xong
A24: ="TV1 – "&'Thành viên'!B4 -> TV1 – Phạm Ngọc Trung | B24: =COUNTIFS('GĐ1 Quản lý dự án'!$H$5:$H$300,"TV1") -> 3 | C24: =IF(B24=0,0,COUNTIFS('GĐ1 Quản lý dự án'!$H$5:$H$300,"TV1",'GĐ1 Quản lý dự án'!$N$5:$N$300,"Đã làm")/B24) -> 0 | D24: =COUNTIFS('GĐ2 Phân tích yêu cầu'!$H$5:$H$300,"TV1") -> 3 | E24: =IF(D24=0,0,COUNTIFS('GĐ2 Phân tích yêu cầu'!$H$5:$H$300,"TV1",'GĐ2 Phân tích yêu cầu'!$N$5:$N$300,"Đã làm")/D24) -> 0 | F24: =COUNTIFS('GĐ3 Thiết kế'!$H$5:$H$300,"TV1") -> 4 | G24: =IF(F24=0,0,COUNTIFS('GĐ3 Thiết kế'!$H$5:$H$300,"TV1",'GĐ3 Thiết kế'!$N$5:$N$300,"Đã làm")/F24) -> 0 | H24: =COUNTIFS('GĐ4 Lập trình'!$H$5:$H$300,"TV1") -> 7 | I24: =IF(H24=0,0,COUNTIFS('GĐ4 Lập trình'!$H$5:$H$300,"TV1",'GĐ4 Lập trình'!$N$5:$N$300,"Đã làm")/H24) -> 0 | J24: =COUNTIFS('GĐ5 Kiểm thử'!$H$5:$H$300,"TV1") -> 2 | K24: =IF(J24=0,0,COUNTIFS('GĐ5 Kiểm thử'!$H$5:$H$300,"TV1",'GĐ5 Kiểm thử'!$N$5:$N$300,"Đã làm")/J24) -> 0 | L24: =COUNTIFS('GĐ6 Triển khai và bảo vệ'!$H$5:$H$300,"TV1") -> 2 | M24: =IF(L24=0,0,COUNTIFS('GĐ6 Triển khai và bảo vệ'!$H$5:$H$300,"TV1",'GĐ6 Triển khai và bảo vệ'!$N$5:$N$300,"Đã làm")/L24) -> 0
A25: ="TV2 – "&'Thành viên'!B5 -> TV2 – Trần Quốc Anh Hoàng | B25: =COUNTIFS('GĐ1 Quản lý dự án'!$H$5:$H$300,"TV2") -> 2 | C25: =IF(B25=0,0,COUNTIFS('GĐ1 Quản lý dự án'!$H$5:$H$300,"TV2",'GĐ1 Quản lý dự án'!$N$5:$N$300,"Đã làm")/B25) -> 0 | D25: =COUNTIFS('GĐ2 Phân tích yêu cầu'!$H$5:$H$300,"TV2") -> 2 | E25: =IF(D25=0,0,COUNTIFS('GĐ2 Phân tích yêu cầu'!$H$5:$H$300,"TV2",'GĐ2 Phân tích yêu cầu'!$N$5:$N$300,"Đã làm")/D25) -> 0 | F25: =COUNTIFS('GĐ3 Thiết kế'!$H$5:$H$300,"TV2") -> 4 | G25: =IF(F25=0,0,COUNTIFS('GĐ3 Thiết kế'!$H$5:$H$300,"TV2",'GĐ3 Thiết kế'!$N$5:$N$300,"Đã làm")/F25) -> 0 | H25: =COUNTIFS('GĐ4 Lập trình'!$H$5:$H$300,"TV2") -> 4 | I25: =IF(H25=0,0,COUNTIFS('GĐ4 Lập trình'!$H$5:$H$300,"TV2",'GĐ4 Lập trình'!$N$5:$N$300,"Đã làm")/H25) -> 0 | J25: =COUNTIFS('GĐ5 Kiểm thử'!$H$5:$H$300,"TV2") -> 2 | K25: =IF(J25=0,0,COUNTIFS('GĐ5 Kiểm thử'!$H$5:$H$300,"TV2",'GĐ5 Kiểm thử'!$N$5:$N$300,"Đã làm")/J25) -> 0 | L25: =COUNTIFS('GĐ6 Triển khai và bảo vệ'!$H$5:$H$300,"TV2") -> 3 | M25: =IF(L25=0,0,COUNTIFS('GĐ6 Triển khai và bảo vệ'!$H$5:$H$300,"TV2",'GĐ6 Triển khai và bảo vệ'!$N$5:$N$300,"Đã làm")/L25) -> 0
A26: ="TV3 – "&'Thành viên'!B6 -> TV3 – Nguyễn Văn Thu | B26: =COUNTIFS('GĐ1 Quản lý dự án'!$H$5:$H$300,"TV3") -> 1 | C26: =IF(B26=0,0,COUNTIFS('GĐ1 Quản lý dự án'!$H$5:$H$300,"TV3",'GĐ1 Quản lý dự án'!$N$5:$N$300,"Đã làm")/B26) -> 0 | D26: =COUNTIFS('GĐ2 Phân tích yêu cầu'!$H$5:$H$300,"TV3") -> 4 | E26: =IF(D26=0,0,COUNTIFS('GĐ2 Phân tích yêu cầu'!$H$5:$H$300,"TV3",'GĐ2 Phân tích yêu cầu'!$N$5:$N$300,"Đã làm")/D26) -> 0 | F26: =COUNTIFS('GĐ3 Thiết kế'!$H$5:$H$300,"TV3") -> 3 | G26: =IF(F26=0,0,COUNTIFS('GĐ3 Thiết kế'!$H$5:$H$300,"TV3",'GĐ3 Thiết kế'!$N$5:$N$300,"Đã làm")/F26) -> 0 | H26: =COUNTIFS('GĐ4 Lập trình'!$H$5:$H$300,"TV3") -> 6 | I26: =IF(H26=0,0,COUNTIFS('GĐ4 Lập trình'!$H$5:$H$300,"TV3",'GĐ4 Lập trình'!$N$5:$N$300,"Đã làm")/H26) -> 0 | J26: =COUNTIFS('GĐ5 Kiểm thử'!$H$5:$H$300,"TV3") -> 3 | K26: =IF(J26=0,0,COUNTIFS('GĐ5 Kiểm thử'!$H$5:$H$300,"TV3",'GĐ5 Kiểm thử'!$N$5:$N$300,"Đã làm")/J26) -> 0 | L26: =COUNTIFS('GĐ6 Triển khai và bảo vệ'!$H$5:$H$300,"TV3") -> 2 | M26: =IF(L26=0,0,COUNTIFS('GĐ6 Triển khai và bảo vệ'!$H$5:$H$300,"TV3",'GĐ6 Triển khai và bảo vệ'!$N$5:$N$300,"Đã làm")/L26) -> 0

Sheet GĐ1 Quản lý dự án
A1: GIAI ĐOẠN 1 – QUẢN LÝ DỰ ÁN
A2: Điều phối nhóm, theo dõi tiến độ, quản lý tài liệu, rủi ro và thay đổi yêu cầu trong suốt học kỳ.
A4: Mã CV | B4: Công việc | C4: Mô tả chi tiết (các bước thực hiện) | D4: Đầu vào cần có | E4: Kết quả đầu ra | F4: Tiêu chí hoàn thành | G4: Liên quan (UC / BR / NFR) | H4: Mã TV | I4: Người thực hiện | J4: Mã người review | K4: Người review | L4: Bắt đầu | M4: Hạn | N4: Trạng thái | O4: Ghi chú
A5: ="TV1 – "&'Thành viên'!B4&" – "&'Thành viên'!E4 -> TV1 – Phạm Ngọc Trung – Backend, AI, triển khai
A6: GĐ1-01 | B6: Thiết lập và quản lý workspace GitHub | C6: 1. Tạo repository it-onsite theo cấu trúc: backend/, frontend/, docs/, infra/, .github/workflows/. 2. Mời 2 thành viên với quyền Write. 3. Tạo nhánh main và develop; bật bảo vệ nhánh: chỉ cập nhật qua Pull Request, cần ít nhất 1 người review. 4. Tạo GitHub Projects gồm 4 cột: Todo, In progress, Review, Done. 5. Tạo Issue cho từng công việc trong file này, đặt tên theo mã công việc (ví dụ GĐ2-04), gán người phụ trách và nhãn giai đoạn. 6. Viết README.md: giới thiệu đề tài, cấu trúc thư mục, quy ước nhánh feature/<mã công việc>-<tên ngắn>, quy ước commit (feat, fix, docs, test, refactor, chore). | D6: SRS v0.1 mục 7.2; file giao việc này | E6: Repository GitHub, board GitHub Projects, README.md | F6: Cả 3 thành viên tạo được nhánh, push và mở Pull Request thử vào develop thành công; board có đủ Issue của giai đoạn 1–3. | G6: SRS 7.2; D4 | H6: TV1 | I6: =IF(H6="","",IFERROR(IF(INDEX('Thành viên'!$B$4:$B$6,MATCH(H6,'Thành viên'!$A$4:$A$6,0))="","",INDEX('Thành viên'!$B$4:$B$6,MATCH(H6,'Thành viên'!$A$4:$A$6,0))),"")) -> Phạm Ngọc Trung | J6: TV3 | K6: =IF(J6="","",IFERROR(IF(INDEX('Thành viên'!$B$4:$B$6,MATCH(J6,'Thành viên'!$A$4:$A$6,0))="","",INDEX('Thành viên'!$B$4:$B$6,MATCH(J6,'Thành viên'!$A$4:$A$6,0))),"")) -> Nguyễn Văn Thu | N6: Chưa làm
A7: GĐ1-02 | B7: Chủ trì họp nhóm hằng tuần và làm việc với giảng viên | C7: 1. Họp nhóm 1 lần/tuần (30–45 phút): mỗi người báo việc đã làm, việc tuần tới, vướng mắc. 2. Chốt việc tuần tới và cập nhật lên board GitHub. 3. Trước mỗi buổi học: chuẩn bị nội dung báo cáo tiến độ cho giảng viên. 4. Sau mỗi buổi học: chuyển từng góp ý của giảng viên thành Issue có người phụ trách và báo TV3 ghi vào nhật ký thay đổi yêu cầu (GĐ1-06). | D7: Biên bản họp (GĐ1-04); board GitHub | E7: Danh sách góp ý của giảng viên kèm Issue tương ứng | F7: Mọi góp ý của giảng viên đều có Issue và người phụ trách trong vòng 2 ngày sau buổi học. | G7: — | H7: TV1 | I7: =IF(H7="","",IFERROR(IF(INDEX('Thành viên'!$B$4:$B$6,MATCH(H7,'Thành viên'!$A$4:$A$6,0))="","",INDEX('Thành viên'!$B$4:$B$6,MATCH(H7,'Thành viên'!$A$4:$A$6,0))),"")) -> Phạm Ngọc Trung | K7: =IF(J7="","",IFERROR(IF(INDEX('Thành viên'!$B$4:$B$6,MATCH(J7,'Thành viên'!$A$4:$A$6,0))="","",INDEX('Thành viên'!$B$4:$B$6,MATCH(J7,'Thành viên'!$A$4:$A$6,0))),"")) | N7: Chưa làm
A8: GĐ1-03 | B8: Theo dõi tiến độ và review Pull Request | C8: 1. Cuối mỗi tuần: đối chiếu cột Trạng thái trong file này với board GitHub, cập nhật cho khớp. 2. Nhắc thành viên có công việc sát hạn hoặc quá hạn (xem sheet Tiến độ). 3. Review Pull Request phần tài liệu và giao diện trong vòng 48 giờ: đúng yêu cầu, đúng quy ước, không làm hỏng chức năng cũ. 4. Khi một thành viên quá tải: đề xuất điều chỉnh phân công trong buổi họp. | D8: File giao việc; board GitHub | E8: File giao việc và board được cập nhật hằng tuần | F8: Không có Pull Request chờ review quá 48 giờ; file và board khớp nhau tại mỗi buổi họp. | G8: — | H8: TV1 | I8: =IF(H8="","",IFERROR(IF(INDEX('Thành viên'!$B$4:$B$6,MATCH(H8,'Thành viên'!$A$4:$A$6,0))="","",INDEX('Thành viên'!$B$4:$B$6,MATCH(H8,'Thành viên'!$A$4:$A$6,0))),"")) -> Phạm Ngọc Trung | K8: =IF(J8="","",IFERROR(IF(INDEX('Thành viên'!$B$4:$B$6,MATCH(J8,'Thành viên'!$A$4:$A$6,0))="","",INDEX('Thành viên'!$B$4:$B$6,MATCH(J8,'Thành viên'!$A$4:$A$6,0))),"")) | N8: Chưa làm
A9: ="TV2 – "&'Thành viên'!B5&" – "&'Thành viên'!E5 -> TV2 – Trần Quốc Anh Hoàng – Frontend, giao diện
A10: GĐ1-04 | B10: Ghi biên bản họp nhóm | C10: 1. Tạo mẫu biên bản gồm: ngày họp, người tham dự, nội dung từng người báo cáo, quyết định của nhóm, việc được giao (người làm, hạn). 2. Ghi biên bản ở mỗi buổi họp nhóm và mỗi buổi làm việc với giảng viên. 3. Lưu tại docs/meetings/ với tên YYYY-MM-DD.md. 4. Gửi link biên bản vào nhóm chat trong vòng 24 giờ sau buổi họp. | D10: — | E10: Bộ biên bản họp theo từng tuần | F10: Đủ biên bản cho mọi buổi họp; mỗi biên bản có mục "Quyết định" và "Việc được giao". | G10: — | H10: TV2 | I10: =IF(H10="","",IFERROR(IF(INDEX('Thành viên'!$B$4:$B$6,MATCH(H10,'Thành viên'!$A$4:$A$6,0))="","",INDEX('Thành viên'!$B$4:$B$6,MATCH(H10,'Thành viên'!$A$4:$A$6,0))),"")) -> Trần Quốc Anh Hoàng | J10: TV1 | K10: =IF(J10="","",IFERROR(IF(INDEX('Thành viên'!$B$4:$B$6,MATCH(J10,'Thành viên'!$A$4:$A$6,0))="","",INDEX('Thành viên'!$B$4:$B$6,MATCH(J10,'Thành viên'!$A$4:$A$6,0))),"")) -> Phạm Ngọc Trung | N10: Chưa làm
A11: GĐ1-05 | B11: Quản lý kho tài liệu chung | C11: 1. Tạo thư mục chung trên OneDrive của trường, chia sẻ quyền chỉnh sửa cho nhóm. 2. Chia thư mục: 01-SRS, 02-SAD, 03-CSDL, 04-KiemThu, 05-BaoCao, 06-HinhAnh, 99-LuuTru. 3. Quy ước tên file: <LoaiTaiLieu>_IT_OnSite_v<x.y>.<đuôi> (ví dụ SRS_IT_OnSite_v1.0.docx). 4. Mỗi khi có bản mới: giữ bản mới nhất ở thư mục chính, chuyển bản cũ vào 99-LuuTru. 5. Định kỳ đồng bộ bản chính thức của tài liệu vào thư mục docs/ trong repository. | D11: — | E11: Thư mục tài liệu chung có cấu trúc thống nhất | F11: Mỗi loại tài liệu chỉ có một bản mới nhất ở thư mục chính; bản trong docs/ của repository trùng với bản mới nhất. | G11: — | H11: TV2 | I11: =IF(H11="","",IFERROR(IF(INDEX('Thành viên'!$B$4:$B$6,MATCH(H11,'Thành viên'!$A$4:$A$6,0))="","",INDEX('Thành viên'!$B$4:$B$6,MATCH(H11,'Thành viên'!$A$4:$A$6,0))),"")) -> Trần Quốc Anh Hoàng | J11: TV1 | K11: =IF(J11="","",IFERROR(IF(INDEX('Thành viên'!$B$4:$B$6,MATCH(J11,'Thành viên'!$A$4:$A$6,0))="","",INDEX('Thành viên'!$B$4:$B$6,MATCH(J11,'Thành viên'!$A$4:$A$6,0))),"")) -> Phạm Ngọc Trung | N11: Chưa làm
A12: ="TV3 – "&'Thành viên'!B6&" – "&'Thành viên'!E6 -> TV3 – Nguyễn Văn Thu – Phân tích nghiệp vụ, kiểm thử, tài liệu
A13: GĐ1-06 | B13: Quản lý rủi ro và thay đổi yêu cầu | C13: 1. Lập bảng rủi ro: mô tả, khả năng xảy ra (thấp/trung bình/cao), mức ảnh hưởng, biện pháp phòng ngừa, người theo dõi. 2. Đưa vào các rủi ro ban đầu: Gemini API lỗi hoặc hết hạn mức; thành viên trễ việc; yêu cầu thay đổi muộn; không đủ người tham gia khảo sát; triển khai máy chủ lỗi sát ngày bảo vệ. 3. Lập nhật ký thay đổi yêu cầu: ngày, nguồn (giảng viên, chủ dịch vụ, khảo sát), nội dung thay đổi, UC/BR/NFR bị ảnh hưởng, quyết định của nhóm. 4. Cập nhật cả hai bảng sau mỗi buổi họp và mỗi buổi làm việc với giảng viên. | D13: Góp ý của giảng viên; biên bản họp (GĐ1-04) | E13: docs/quan-ly/RuiRo_ThayDoi.xlsx gồm 2 sheet: Rủi ro, Thay đổi yêu cầu | F13: Mọi thay đổi của SRS v1.0 so với v0.1 đều truy được về một dòng trong nhật ký thay đổi. | G13: — | H13: TV3 | I13: =IF(H13="","",IFERROR(IF(INDEX('Thành viên'!$B$4:$B$6,MATCH(H13,'Thành viên'!$A$4:$A$6,0))="","",INDEX('Thành viên'!$B$4:$B$6,MATCH(H13,'Thành viên'!$A$4:$A$6,0))),"")) -> Nguyễn Văn Thu | J13: TV1 | K13: =IF(J13="","",IFERROR(IF(INDEX('Thành viên'!$B$4:$B$6,MATCH(J13,'Thành viên'!$A$4:$A$6,0))="","",INDEX('Thành viên'!$B$4:$B$6,MATCH(J13,'Thành viên'!$A$4:$A$6,0))),"")) -> Phạm Ngọc Trung | N13: Chưa làm

Sheet GĐ2 Phân tích yêu cầu
A1: GIAI ĐOẠN 2 – PHÂN TÍCH YÊU CẦU
A2: Hoàn thiện SRS v1.0. Phân tích xuất phát từ quy trình làm việc thực tế của dịch vụ và các use case, theo góp ý của giảng viên.
A4: Mã CV | B4: Công việc | C4: Mô tả chi tiết (các bước thực hiện) | D4: Đầu vào cần có | E4: Kết quả đầu ra | F4: Tiêu chí hoàn thành | G4: Liên quan (UC / BR / NFR) | H4: Mã TV | I4: Người thực hiện | J4: Mã người review | K4: Người review | L4: Bắt đầu | M4: Hạn | N4: Trạng thái | O4: Ghi chú
A5: ="TV1 – "&'Thành viên'!B4&" – "&'Thành viên'!E4 -> TV1 – Phạm Ngọc Trung – Backend, AI, triển khai
A6: GĐ2-01 | B6: Soạn tài liệu chính sách vận hành của dịch vụ | C6: 1. Với vai trò chủ dịch vụ, viết rõ quy trình làm việc thực tế từ lúc nhận liên hệ của khách tới lúc thu tiền và bảo hành. Hoàn thành phần này đầu tiên để TV3 vẽ quy trình (GĐ2-07). 2. Chốt các tham số nghiệp vụ: phí khảo sát; thời hạn hủy miễn phí; thời hạn kỹ thuật viên phản hồi; thời gian đệm di chuyển; giờ phục vụ; khu vực phục vụ. 3. Chốt bảng giá ban đầu: tên dịch vụ, đơn giá, thời lượng ước tính, thời hạn bảo hành. 4. Ghi nguồn cho từng con số (quyết định của chủ dịch vụ, tham khảo giá thị trường…). | D6: SRS v0.1 mục 3.4 (BR-02 đến BR-07); Phụ lục A.1 | E6: docs/01-SRS/ChinhSachVanHanh.docx gồm quy trình thực tế, bảng tham số, bảng giá | F6: Mọi con số dùng trong BR-02, BR-03, BR-04, BR-06, BR-07 đều có trong tài liệu và có nguồn. | G6: BR-02, BR-03, BR-04, BR-06, BR-07; UC19; UC23 | H6: TV1 | I6: =IF(H6="","",IFERROR(IF(INDEX('Thành viên'!$B$4:$B$6,MATCH(H6,'Thành viên'!$A$4:$A$6,0))="","",INDEX('Thành viên'!$B$4:$B$6,MATCH(H6,'Thành viên'!$A$4:$A$6,0))),"")) -> Phạm Ngọc Trung | J6: TV3 | K6: =IF(J6="","",IFERROR(IF(INDEX('Thành viên'!$B$4:$B$6,MATCH(J6,'Thành viên'!$A$4:$A$6,0))="","",INDEX('Thành viên'!$B$4:$B$6,MATCH(J6,'Thành viên'!$A$4:$A$6,0))),"")) -> Nguyễn Văn Thu | N6: Chưa làm
A7: GĐ2-02 | B7: Đặc tả use case nhóm điều phối – báo giá – thanh toán | C7: 1. Đặc tả UC08, UC09, UC10, UC11, UC12, UC13, UC14 theo đúng mẫu ở SRS v0.1 mục 3.5: actor chính/phụ, mô tả, tiền điều kiện, hậu điều kiện, luồng chính, luồng thay thế, ngoại lệ, quy tắc liên quan. 2. Mỗi bước trong luồng chính phải ứng với một bước thật trong quy trình làm việc của dịch vụ; ghi mã bước quy trình (P01, P02…) khi có sơ đồ quy trình của TV3 (GĐ2-07). 3. Ghi rõ trạng thái phiếu trước và sau của mỗi use case, khớp sơ đồ trạng thái SRS mục 3.3. 4. Vẽ sơ đồ hoạt động cho UC08 và UC10. | D7: SRS v0.1; tài liệu chính sách vận hành (GĐ2-01) | E7: 7 bản đặc tả use case + 2 sơ đồ hoạt động, gửi TV3 tổng hợp | F7: Đủ 7 use case; mỗi use case có ít nhất 1 luồng thay thế hoặc ngoại lệ; trạng thái phiếu khớp sơ đồ trạng thái. | G7: UC08–UC14; BR-01, BR-04, BR-05, BR-06, BR-08, BR-11, BR-13 | H7: TV1 | I7: =IF(H7="","",IFERROR(IF(INDEX('Thành viên'!$B$4:$B$6,MATCH(H7,'Thành viên'!$A$4:$A$6,0))="","",INDEX('Thành viên'!$B$4:$B$6,MATCH(H7,'Thành viên'!$A$4:$A$6,0))),"")) -> Phạm Ngọc Trung | J7: TV3 | K7: =IF(J7="","",IFERROR(IF(INDEX('Thành viên'!$B$4:$B$6,MATCH(J7,'Thành viên'!$A$4:$A$6,0))="","",INDEX('Thành viên'!$B$4:$B$6,MATCH(J7,'Thành viên'!$A$4:$A$6,0))),"")) -> Nguyễn Văn Thu | N7: Chưa làm
A8: GĐ2-03 | B8: Đặc tả UC05 và danh mục sự cố cho AI | C8: 1. Lập danh mục sự cố chính thức (khoảng 8–10 loại): mã, tên, định nghĩa, 3 ví dụ mô tả của khách cho mỗi loại. 2. Ánh xạ mỗi loại sự cố sang dịch vụ mặc định trong bảng giá. 3. Quy định mức khẩn (thấp, trung bình, cao) và tiêu chí xác định từng mức. 4. Cập nhật đặc tả UC05 v1.0 và rà lại NFR-03, NFR-10, NFR-17, NFR-18. | D8: Bảng giá (GĐ2-01); SRS v0.1 mục 3.5.2 | E8: Danh mục sự cố + đặc tả UC05 v1.0 | F8: Mọi loại sự cố ánh xạ được tới một dịch vụ có trong bảng giá; mỗi loại có đủ 3 ví dụ. | G8: UC05; BR-09; NFR-03, NFR-10, NFR-17, NFR-18 | H8: TV1 | I8: =IF(H8="","",IFERROR(IF(INDEX('Thành viên'!$B$4:$B$6,MATCH(H8,'Thành viên'!$A$4:$A$6,0))="","",INDEX('Thành viên'!$B$4:$B$6,MATCH(H8,'Thành viên'!$A$4:$A$6,0))),"")) -> Phạm Ngọc Trung | J8: TV3 | K8: =IF(J8="","",IFERROR(IF(INDEX('Thành viên'!$B$4:$B$6,MATCH(J8,'Thành viên'!$A$4:$A$6,0))="","",INDEX('Thành viên'!$B$4:$B$6,MATCH(J8,'Thành viên'!$A$4:$A$6,0))),"")) -> Nguyễn Văn Thu | N8: Chưa làm
A9: ="TV2 – "&'Thành viên'!B5&" – "&'Thành viên'!E5 -> TV2 – Trần Quốc Anh Hoàng – Frontend, giao diện
A10: GĐ2-04 | B10: Đặc tả use case phân hệ khách hàng | C10: 1. Đặc tả UC01, UC02, UC03, UC04, UC06, UC07, UC15, UC16, UC17 theo mẫu SRS v0.1 mục 3.5 (UC04 cập nhật từ bản có sẵn). 2. Viết theo góc nhìn của khách: ở từng bước khách làm gì, hệ thống phản hồi gì. 3. Đối chiếu quy tắc: BR-02, BR-03 cho UC04 và UC07; BR-07 cho UC15; BR-10 cho UC16. 4. Ghi rõ ở bước nào hệ thống gửi thông báo, gửi cho ai. 5. Ghi mã bước quy trình (P01, P02…) khi có sơ đồ quy trình của TV3 (GĐ2-07). | D10: SRS v0.1 | E10: 9 bản đặc tả use case, gửi TV3 tổng hợp | F10: Đủ 9 use case; mỗi use case có luồng thay thế hoặc ngoại lệ; thông báo gửi cho ai ở bước nào được ghi rõ. | G10: UC01–UC04, UC06, UC07, UC15–UC17; BR-02, BR-03, BR-07, BR-10 | H10: TV2 | I10: =IF(H10="","",IFERROR(IF(INDEX('Thành viên'!$B$4:$B$6,MATCH(H10,'Thành viên'!$A$4:$A$6,0))="","",INDEX('Thành viên'!$B$4:$B$6,MATCH(H10,'Thành viên'!$A$4:$A$6,0))),"")) -> Trần Quốc Anh Hoàng | J10: TV1 | K10: =IF(J10="","",IFERROR(IF(INDEX('Thành viên'!$B$4:$B$6,MATCH(J10,'Thành viên'!$A$4:$A$6,0))="","",INDEX('Thành viên'!$B$4:$B$6,MATCH(J10,'Thành viên'!$A$4:$A$6,0))),"")) -> Phạm Ngọc Trung | N10: Chưa làm
A11: GĐ2-05 | B11: Lập danh sách màn hình và luồng màn hình | C11: 1. Liệt kê toàn bộ màn hình của 4 vai trò (khách hàng, kỹ thuật viên, điều phối viên, quản trị viên) dựa trên SRS mục 6.1. 2. Với mỗi màn hình ghi: mã màn hình, tên, vai trò sử dụng, use case phục vụ, dữ liệu hiển thị, thao tác chính. 3. Vẽ sơ đồ luồng màn hình cho khách hàng và cho kỹ thuật viên (bấm gì thì chuyển sang màn hình nào). | D11: SRS v0.1 mục 3.2, 6.1 | E11: Bảng màn hình – use case + 2 sơ đồ luồng màn hình | F11: Mọi use case có ít nhất một màn hình; không có màn hình nào không phục vụ use case. | G11: UC01–UC23; NFR-11 | H11: TV2 | I11: =IF(H11="","",IFERROR(IF(INDEX('Thành viên'!$B$4:$B$6,MATCH(H11,'Thành viên'!$A$4:$A$6,0))="","",INDEX('Thành viên'!$B$4:$B$6,MATCH(H11,'Thành viên'!$A$4:$A$6,0))),"")) -> Trần Quốc Anh Hoàng | J11: TV1 | K11: =IF(J11="","",IFERROR(IF(INDEX('Thành viên'!$B$4:$B$6,MATCH(J11,'Thành viên'!$A$4:$A$6,0))="","",INDEX('Thành viên'!$B$4:$B$6,MATCH(J11,'Thành viên'!$A$4:$A$6,0))),"")) -> Phạm Ngọc Trung | N11: Chưa làm
A12: ="TV3 – "&'Thành viên'!B6&" – "&'Thành viên'!E6 -> TV3 – Nguyễn Văn Thu – Phân tích nghiệp vụ, kiểm thử, tài liệu
A13: GĐ2-06 | B13: Khảo sát người dùng tiềm năng | C13: 1. Tạo Google Form từ bộ câu hỏi SRS Phụ lục A.2, bổ sung câu hỏi về mức giá chấp nhận được và kênh nhận thông báo. 2. Thu thập tối thiểu 15 phản hồi từ đúng nhóm khách mục tiêu: sinh viên, hộ gia đình, văn phòng nhỏ. 3. Tổng hợp kết quả bằng bảng và biểu đồ. 4. Rút ra kết luận: yêu cầu nào được khẳng định, yêu cầu nào cần thêm hoặc sửa; ghi các thay đổi vào nhật ký thay đổi yêu cầu (GĐ1-06). | D13: SRS v0.1 Phụ lục A.2 | E13: Link Google Form, file kết quả, báo cáo khảo sát 1–2 trang | F13: Có ít nhất 15 phản hồi hợp lệ; mỗi kết luận dẫn chiếu được tới số liệu khảo sát thật. | G13: SRS mục 2.1; Phụ lục A.2 | H13: TV3 | I13: =IF(H13="","",IFERROR(IF(INDEX('Thành viên'!$B$4:$B$6,MATCH(H13,'Thành viên'!$A$4:$A$6,0))="","",INDEX('Thành viên'!$B$4:$B$6,MATCH(H13,'Thành viên'!$A$4:$A$6,0))),"")) -> Nguyễn Văn Thu | J13: TV1 | K13: =IF(J13="","",IFERROR(IF(INDEX('Thành viên'!$B$4:$B$6,MATCH(J13,'Thành viên'!$A$4:$A$6,0))="","",INDEX('Thành viên'!$B$4:$B$6,MATCH(J13,'Thành viên'!$A$4:$A$6,0))),"")) -> Phạm Ngọc Trung | N13: Chưa làm
A14: GĐ2-07 | B14: Phân tích quy trình thực tế và quy trình mới | C14: 1. Từ tài liệu chính sách vận hành (GĐ2-01), vẽ quy trình hiện tại (as-is): khách liên hệ qua điện thoại/Zalo → hẹn lịch → đến nhà → báo giá miệng → sửa → thu tiền. 2. Chỉ ra điểm yếu của từng bước (dựa trên SRS mục 2.1 và kết quả khảo sát). 3. Vẽ quy trình mới khi có hệ thống (to-be) bằng sơ đồ hoạt động có làn (swimlane) cho Khách hàng, Điều phối viên, Kỹ thuật viên, Hệ thống; đánh mã từng bước P01, P02… 4. Lập ma trận truy vết: bước quy trình ↔ use case ↔ quy tắc nghiệp vụ. 5. Gửi danh sách mã bước cho TV1, TV2 sớm nhất có thể để gắn vào đặc tả use case. | D14: GĐ2-01 phần quy trình thực tế; SRS v0.1 | E14: Sơ đồ as-is, sơ đồ to-be, ma trận truy vết (đưa vào SRS v1.0) | F14: Mọi use case xuất hiện ở ít nhất một bước; bước nào làm ngoài hệ thống được ghi rõ "ngoài hệ thống". | G14: UC01–UC23; BR-01–BR-13 | H14: TV3 | I14: =IF(H14="","",IFERROR(IF(INDEX('Thành viên'!$B$4:$B$6,MATCH(H14,'Thành viên'!$A$4:$A$6,0))="","",INDEX('Thành viên'!$B$4:$B$6,MATCH(H14,'Thành viên'!$A$4:$A$6,0))),"")) -> Nguyễn Văn Thu | J14: TV1 | K14: =IF(J14="","",IFERROR(IF(INDEX('Thành viên'!$B$4:$B$6,MATCH(J14,'Thành viên'!$A$4:$A$6,0))="","",INDEX('Thành viên'!$B$4:$B$6,MATCH(J14,'Thành viên'!$A$4:$A$6,0))),"")) -> Phạm Ngọc Trung | N14: Chưa làm
A15: GĐ2-08 | B15: Đặc tả use case phân hệ quản trị | C15: 1. Đặc tả UC18, UC19, UC20, UC21, UC22, UC23 theo mẫu SRS v0.1 mục 3.5. 2. UC21: liệt kê cụ thể từng báo cáo, cách tính từng chỉ số, bộ lọc. 3. UC23: liệt kê từng tham số và giá trị mặc định lấy từ tài liệu chính sách vận hành (GĐ2-01). 4. Ghi mã bước quy trình tương ứng (GĐ2-07). | D15: SRS v0.1; GĐ2-01 | E15: 6 bản đặc tả use case | F15: Đủ 6 use case; mỗi chỉ số báo cáo có công thức tính rõ ràng. | G15: UC18–UC23; BR-13 | H15: TV3 | I15: =IF(H15="","",IFERROR(IF(INDEX('Thành viên'!$B$4:$B$6,MATCH(H15,'Thành viên'!$A$4:$A$6,0))="","",INDEX('Thành viên'!$B$4:$B$6,MATCH(H15,'Thành viên'!$A$4:$A$6,0))),"")) -> Nguyễn Văn Thu | J15: TV1 | K15: =IF(J15="","",IFERROR(IF(INDEX('Thành viên'!$B$4:$B$6,MATCH(J15,'Thành viên'!$A$4:$A$6,0))="","",INDEX('Thành viên'!$B$4:$B$6,MATCH(J15,'Thành viên'!$A$4:$A$6,0))),"")) -> Phạm Ngọc Trung | N15: Chưa làm
A16: GĐ2-09 | B16: Tổng hợp SRS v1.0 | C16: 1. Gộp đặc tả use case của 3 người vào SRS (mục 3.5), thống nhất cách viết và thuật ngữ. 2. Thêm mục phân tích quy trình (as-is, to-be, ma trận truy vết) và kết quả khảo sát. 3. Cập nhật danh sách use case, quy tắc nghiệp vụ, NFR theo chính sách vận hành đã chốt và kết quả khảo sát; cập nhật sơ đồ use case nếu có thay đổi. 4. Định dạng: chỉ dùng màu mặc định, mục lục tự động, đánh số bảng và hình. 5. Gửi TV1 review, sửa theo góp ý, đổi phiên bản thành v1.0 và cập nhật nhật ký thay đổi. | D16: Kết quả GĐ2-01 đến GĐ2-08 | E16: SRS_IT_OnSite_v1.0.docx (D5) | F16: Đủ đặc tả 23 use case; không mâu thuẫn tên trạng thái, tên thực thể, mã BR giữa các phần. | G16: D5 | H16: TV3 | I16: =IF(H16="","",IFERROR(IF(INDEX('Thành viên'!$B$4:$B$6,MATCH(H16,'Thành viên'!$A$4:$A$6,0))="","",INDEX('Thành viên'!$B$4:$B$6,MATCH(H16,'Thành viên'!$A$4:$A$6,0))),"")) -> Nguyễn Văn Thu | J16: TV1 | K16: =IF(J16="","",IFERROR(IF(INDEX('Thành viên'!$B$4:$B$6,MATCH(J16,'Thành viên'!$A$4:$A$6,0))="","",INDEX('Thành viên'!$B$4:$B$6,MATCH(J16,'Thành viên'!$A$4:$A$6,0))),"")) -> Phạm Ngọc Trung | N16: Chưa làm

Sheet GĐ3 Thiết kế
A1: GIAI ĐOẠN 3 – THIẾT KẾ HỆ THỐNG (SAD)
A2: Hoàn thiện tài liệu phân tích thiết kế (SAD v1.0) và lược đồ CSDL, đủ chi tiết để lập trình mà không phải đoán.
A4: Mã CV | B4: Công việc | C4: Mô tả chi tiết (các bước thực hiện) | D4: Đầu vào cần có | E4: Kết quả đầu ra | F4: Tiêu chí hoàn thành | G4: Liên quan (UC / BR / NFR) | H4: Mã TV | I4: Người thực hiện | J4: Mã người review | K4: Người review | L4: Bắt đầu | M4: Hạn | N4: Trạng thái | O4: Ghi chú
A5: ="TV1 – "&'Thành viên'!B4&" – "&'Thành viên'!E4 -> TV1 – Phạm Ngọc Trung – Backend, AI, triển khai
A6: GĐ3-01 | B6: Thiết kế kiến trúc tổng thể | C6: 1. Vẽ sơ đồ kiến trúc: React (giao diện) – FastAPI (REST API) – PostgreSQL – lưu trữ ảnh – Gemini API – Telegram Bot API – máy chủ email. 2. Vẽ sơ đồ triển khai: các container Docker, máy chủ, tên miền và HTTPS. 3. Quy định cấu trúc thư mục backend theo lớp: api (router), schemas, services (nghiệp vụ), repositories (truy cập dữ liệu), models, core (cấu hình, bảo mật). 4. Quy định chung: xác thực JWT (access token, refresh token), định dạng lỗi trả về, ghi log, cấu hình bằng biến môi trường. | D6: SRS v1.0 | E6: Chương "Kiến trúc hệ thống" trong SAD | F6: Mọi hệ thống ngoài trong SRS mục 6.2 có trên sơ đồ; TV2, TV3 đọc xong biết code của mình đặt ở đâu. | G6: SRS 2.3, 6.2, 6.3; NFR-05, NFR-06 | H6: TV1 | I6: =IF(H6="","",IFERROR(IF(INDEX('Thành viên'!$B$4:$B$6,MATCH(H6,'Thành viên'!$A$4:$A$6,0))="","",INDEX('Thành viên'!$B$4:$B$6,MATCH(H6,'Thành viên'!$A$4:$A$6,0))),"")) -> Phạm Ngọc Trung | J6: TV3 | K6: =IF(J6="","",IFERROR(IF(INDEX('Thành viên'!$B$4:$B$6,MATCH(J6,'Thành viên'!$A$4:$A$6,0))="","",INDEX('Thành viên'!$B$4:$B$6,MATCH(J6,'Thành viên'!$A$4:$A$6,0))),"")) -> Nguyễn Văn Thu | N6: Chưa làm
A7: GĐ3-02 | B7: Thiết kế cơ sở dữ liệu | C7: 1. Vẽ ERD từ các thực thể ở SRS chương 4. 2. Với mỗi bảng: cột, kiểu dữ liệu, khóa chính, khóa ngoại, ràng buộc unique/check (ví dụ trạng thái phiếu chỉ nhận các giá trị trong sơ đồ trạng thái, số sao từ 1 đến 5), chỉ mục. 3. Thêm cột phiên bản cho bảng phiếu yêu cầu (chống hai người sửa cùng lúc) và cột thời gian tạo/cập nhật cho mọi bảng. 4. Viết script tạo bảng cho PostgreSQL 16 và script dữ liệu mẫu (dịch vụ, khu vực, cấu hình, tài khoản quản trị). 5. Viết từ điển dữ liệu: mô tả từng bảng, từng cột. | D7: SRS v1.0 chương 4; tài liệu chính sách vận hành (GĐ2-01) | E7: ERD; docs/03-CSDL/schema.sql, seed.sql; từ điển dữ liệu trong SAD (D7) | F7: Chạy schema.sql và seed.sql trên PostgreSQL 16 không lỗi; mọi thực thể trong SRS có bảng tương ứng. | G7: SRS chương 4; BR-12, BR-13; NFR-07, NFR-08; D7 | H7: TV1 | I7: =IF(H7="","",IFERROR(IF(INDEX('Thành viên'!$B$4:$B$6,MATCH(H7,'Thành viên'!$A$4:$A$6,0))="","",INDEX('Thành viên'!$B$4:$B$6,MATCH(H7,'Thành viên'!$A$4:$A$6,0))),"")) -> Phạm Ngọc Trung | J7: TV3 | K7: =IF(J7="","",IFERROR(IF(INDEX('Thành viên'!$B$4:$B$6,MATCH(J7,'Thành viên'!$A$4:$A$6,0))="","",INDEX('Thành viên'!$B$4:$B$6,MATCH(J7,'Thành viên'!$A$4:$A$6,0))),"")) -> Nguyễn Văn Thu | N7: Chưa làm
A8: GĐ3-03 | B8: Thiết kế API | C8: 1. Liệt kê endpoint cho từng use case: phương thức, đường dẫn, vai trò được gọi, dữ liệu gửi lên, dữ liệu trả về, mã lỗi. 2. Thống nhất quy ước: tiền tố /api/v1, phân trang, lọc, sắp xếp, định dạng lỗi chung. 3. Viết thành file OpenAPI để TV2 làm giao diện và TV3 làm các module phụ theo cùng một hợp đồng. | D8: SRS v1.0; thiết kế CSDL (GĐ3-02) | E8: docs/02-SAD/openapi.yaml + bảng tổng hợp endpoint trong SAD | F8: Mọi use case có endpoint; mỗi endpoint ghi rõ vai trò được phép gọi. | G8: UC01–UC23; NFR-05, NFR-16 | H8: TV1 | I8: =IF(H8="","",IFERROR(IF(INDEX('Thành viên'!$B$4:$B$6,MATCH(H8,'Thành viên'!$A$4:$A$6,0))="","",INDEX('Thành viên'!$B$4:$B$6,MATCH(H8,'Thành viên'!$A$4:$A$6,0))),"")) -> Phạm Ngọc Trung | J8: TV2 | K8: =IF(J8="","",IFERROR(IF(INDEX('Thành viên'!$B$4:$B$6,MATCH(J8,'Thành viên'!$A$4:$A$6,0))="","",INDEX('Thành viên'!$B$4:$B$6,MATCH(J8,'Thành viên'!$A$4:$A$6,0))),"")) -> Trần Quốc Anh Hoàng | N8: Chưa làm
A9: GĐ3-04 | B9: Thiết kế module AI phân loại sự cố | C9: 1. Viết prompt cho Gemini dùng danh mục sự cố (GĐ2-03), yêu cầu trả về JSON theo lược đồ cố định: loại sự cố, độ tin cậy, mức khẩn, lý do ngắn. 2. Thiết kế bộ lọc dữ liệu cá nhân trước khi gửi (số điện thoại, email, địa chỉ, mật khẩu). 3. Thiết kế xử lý lỗi: quá 10 giây thì bỏ qua; JSON sai thì gửi lại 1 lần; độ tin cậy dưới 0,6 thì đánh dấu cần điều phối viên xác nhận. 4. Thiết kế cách lưu kết quả (bảng KetQuaAI, phiên bản prompt) và phương pháp đánh giá độ chính xác. | D9: Danh mục sự cố (GĐ2-03); đặc tả UC05 | E9: Chương "Thiết kế module AI" trong SAD | F9: Có đủ prompt, lược đồ JSON, quy tắc lọc dữ liệu và cách xử lý từng loại lỗi. | G9: UC05; BR-09; NFR-03, NFR-10, NFR-17, NFR-18 | H9: TV1 | I9: =IF(H9="","",IFERROR(IF(INDEX('Thành viên'!$B$4:$B$6,MATCH(H9,'Thành viên'!$A$4:$A$6,0))="","",INDEX('Thành viên'!$B$4:$B$6,MATCH(H9,'Thành viên'!$A$4:$A$6,0))),"")) -> Phạm Ngọc Trung | J9: TV3 | K9: =IF(J9="","",IFERROR(IF(INDEX('Thành viên'!$B$4:$B$6,MATCH(J9,'Thành viên'!$A$4:$A$6,0))="","",INDEX('Thành viên'!$B$4:$B$6,MATCH(J9,'Thành viên'!$A$4:$A$6,0))),"")) -> Nguyễn Văn Thu | N9: Chưa làm
A10: ="TV2 – "&'Thành viên'!B5&" – "&'Thành viên'!E5 -> TV2 – Trần Quốc Anh Hoàng – Frontend, giao diện
A11: GĐ3-05 | B11: Wireframe toàn bộ màn hình | C11: 1. Dựa trên bảng màn hình (GĐ2-05), vẽ wireframe trên Figma cho tất cả màn hình. 2. Khách hàng và kỹ thuật viên: thiết kế cho điện thoại, chiều rộng 360 px. 3. Điều phối viên và quản trị viên: thiết kế cho máy tính. 4. Gắn mã màn hình và mã use case lên từng khung. | D11: Bảng màn hình và luồng màn hình (GĐ2-05) | E11: Link Figma; ảnh wireframe đưa vào SAD | F11: Đủ mọi màn hình trong bảng màn hình; mỗi khung có mã màn hình và mã use case. | G11: UC01–UC23; NFR-11, NFR-12 | H11: TV2 | I11: =IF(H11="","",IFERROR(IF(INDEX('Thành viên'!$B$4:$B$6,MATCH(H11,'Thành viên'!$A$4:$A$6,0))="","",INDEX('Thành viên'!$B$4:$B$6,MATCH(H11,'Thành viên'!$A$4:$A$6,0))),"")) -> Trần Quốc Anh Hoàng | J11: TV1 | K11: =IF(J11="","",IFERROR(IF(INDEX('Thành viên'!$B$4:$B$6,MATCH(J11,'Thành viên'!$A$4:$A$6,0))="","",INDEX('Thành viên'!$B$4:$B$6,MATCH(J11,'Thành viên'!$A$4:$A$6,0))),"")) -> Phạm Ngọc Trung | N11: Chưa làm
A12: GĐ3-06 | B12: Mockup chi tiết màn hình chính và bộ thành phần giao diện | C12: 1. Thiết kế mockup hoàn chỉnh cho các màn hình chính: tạo yêu cầu (nhiều bước), chi tiết phiếu (dòng thời gian trạng thái), duyệt báo giá, thanh toán VietQR, lịch việc của kỹ thuật viên, lập báo giá, bảng điều phối. 2. Xây bộ thành phần dùng chung: nút, ô nhập, bảng, thẻ trạng thái phiếu, thông báo lỗi, hộp xác nhận. 3. Thể hiện đủ các trạng thái của màn hình: đang tải, không có dữ liệu, lỗi. | D12: Wireframe (GĐ3-05) | E12: Mockup trên Figma; ảnh đưa vào SAD | F12: 7 màn hình chính có mockup đủ 3 trạng thái: đang tải, không có dữ liệu, lỗi. | G12: UC04, UC06, UC08, UC10, UC11, UC12, UC14 | H12: TV2 | I12: =IF(H12="","",IFERROR(IF(INDEX('Thành viên'!$B$4:$B$6,MATCH(H12,'Thành viên'!$A$4:$A$6,0))="","",INDEX('Thành viên'!$B$4:$B$6,MATCH(H12,'Thành viên'!$A$4:$A$6,0))),"")) -> Trần Quốc Anh Hoàng | J12: TV1 | K12: =IF(J12="","",IFERROR(IF(INDEX('Thành viên'!$B$4:$B$6,MATCH(J12,'Thành viên'!$A$4:$A$6,0))="","",INDEX('Thành viên'!$B$4:$B$6,MATCH(J12,'Thành viên'!$A$4:$A$6,0))),"")) -> Phạm Ngọc Trung | N12: Chưa làm
A13: GĐ3-07 | B13: Thiết kế phía giao diện (frontend) | C13: 1. Quy định cấu trúc thư mục React: pages, components, services (gọi API), hooks, routes. 2. Thiết kế phân quyền trên giao diện: điều hướng theo vai trò sau khi đăng nhập, chặn truy cập trang không đúng vai trò. 3. Thiết kế cách lưu và làm mới token, xử lý khi hết phiên đăng nhập. 4. Quy định kiểm tra dữ liệu trên form và cách hiển thị lỗi trả về từ API. | D13: Kiến trúc tổng thể (GĐ3-01) | E13: Chương "Thiết kế giao diện" trong SAD | F13: Có sơ đồ điều hướng theo vai trò và quy ước thư mục rõ ràng. | G13: NFR-05, NFR-11 | H13: TV2 | I13: =IF(H13="","",IFERROR(IF(INDEX('Thành viên'!$B$4:$B$6,MATCH(H13,'Thành viên'!$A$4:$A$6,0))="","",INDEX('Thành viên'!$B$4:$B$6,MATCH(H13,'Thành viên'!$A$4:$A$6,0))),"")) -> Trần Quốc Anh Hoàng | J13: TV1 | K13: =IF(J13="","",IFERROR(IF(INDEX('Thành viên'!$B$4:$B$6,MATCH(J13,'Thành viên'!$A$4:$A$6,0))="","",INDEX('Thành viên'!$B$4:$B$6,MATCH(J13,'Thành viên'!$A$4:$A$6,0))),"")) -> Phạm Ngọc Trung | N13: Chưa làm
A14: GĐ3-08 | B14: Sơ đồ hoạt động cho use case phân hệ khách hàng | C14: 1. Vẽ sơ đồ hoạt động cho UC04, UC07, UC15, UC16, thể hiện đủ các nhánh rẽ (ví dụ hủy trước hoặc sau mốc thời gian ở UC07, còn hoặc hết hạn bảo hành ở UC15). 2. Mỗi sơ đồ dựa trên đặc tả use case đã làm ở GĐ2-04 và quy trình to-be (GĐ2-07). | D14: Đặc tả use case (GĐ2-04); quy trình to-be (GĐ2-07) | E14: 4 sơ đồ hoạt động, gửi TV3 đưa vào SAD | F14: Mỗi nhánh rẽ trong sơ đồ ứng với một luồng thay thế hoặc ngoại lệ trong đặc tả. | G14: UC04, UC07, UC15, UC16; BR-03, BR-07, BR-10 | H14: TV2 | I14: =IF(H14="","",IFERROR(IF(INDEX('Thành viên'!$B$4:$B$6,MATCH(H14,'Thành viên'!$A$4:$A$6,0))="","",INDEX('Thành viên'!$B$4:$B$6,MATCH(H14,'Thành viên'!$A$4:$A$6,0))),"")) -> Trần Quốc Anh Hoàng | J14: TV3 | K14: =IF(J14="","",IFERROR(IF(INDEX('Thành viên'!$B$4:$B$6,MATCH(J14,'Thành viên'!$A$4:$A$6,0))="","",INDEX('Thành viên'!$B$4:$B$6,MATCH(J14,'Thành viên'!$A$4:$A$6,0))),"")) -> Nguyễn Văn Thu | N14: Chưa làm
A15: ="TV3 – "&'Thành viên'!B6&" – "&'Thành viên'!E6 -> TV3 – Nguyễn Văn Thu – Phân tích nghiệp vụ, kiểm thử, tài liệu
A16: GĐ3-09 | B16: Sơ đồ lớp (mô hình miền) | C16: 1. Vẽ sơ đồ lớp mức phân tích từ các thực thể và quy tắc nghiệp vụ: lớp, thuộc tính chính, quan hệ, bội số. 2. Thể hiện các phương thức nghiệp vụ quan trọng (ví dụ chuyển trạng thái phiếu, duyệt báo giá, kiểm tra bảo hành). 3. Cập nhật sơ đồ trạng thái phiếu nếu SRS v1.0 có thay đổi. 4. Đối chiếu với ERD (GĐ3-02), ghi lại và thống nhất với TV1 các điểm khác biệt. | D16: SRS v1.0 | E16: Sơ đồ lớp + sơ đồ trạng thái phiếu, đưa vào SAD | F16: Tên lớp và thuộc tính khớp với ERD và từ điển dữ liệu. | G16: SRS mục 3.3, chương 4 | H16: TV3 | I16: =IF(H16="","",IFERROR(IF(INDEX('Thành viên'!$B$4:$B$6,MATCH(H16,'Thành viên'!$A$4:$A$6,0))="","",INDEX('Thành viên'!$B$4:$B$6,MATCH(H16,'Thành viên'!$A$4:$A$6,0))),"")) -> Nguyễn Văn Thu | J16: TV1 | K16: =IF(J16="","",IFERROR(IF(INDEX('Thành viên'!$B$4:$B$6,MATCH(J16,'Thành viên'!$A$4:$A$6,0))="","",INDEX('Thành viên'!$B$4:$B$6,MATCH(J16,'Thành viên'!$A$4:$A$6,0))),"")) -> Phạm Ngọc Trung | N16: Chưa làm
A17: GĐ3-10 | B17: Sơ đồ tuần tự cho các use case chính | C17: 1. Vẽ sơ đồ tuần tự cho UC04 (gồm UC05), UC08, UC10, UC11, UC12, UC14. 2. Mỗi sơ đồ đi qua đủ các lớp: người dùng → giao diện → API → nghiệp vụ → CSDL hoặc hệ thống ngoài (Gemini, Telegram). 3. Thể hiện nhánh lỗi chính (ví dụ AI quá thời gian chờ, hai điều phối viên phân công cùng lúc). | D17: SRS v1.0; kiến trúc tổng thể (GĐ3-01) | E17: 6 sơ đồ tuần tự, đưa vào SAD | F17: Mỗi sơ đồ khớp luồng chính của đặc tả use case tương ứng. | G17: UC04, UC05, UC08, UC10, UC11, UC12, UC14 | H17: TV3 | I17: =IF(H17="","",IFERROR(IF(INDEX('Thành viên'!$B$4:$B$6,MATCH(H17,'Thành viên'!$A$4:$A$6,0))="","",INDEX('Thành viên'!$B$4:$B$6,MATCH(H17,'Thành viên'!$A$4:$A$6,0))),"")) -> Nguyễn Văn Thu | J17: TV1 | K17: =IF(J17="","",IFERROR(IF(INDEX('Thành viên'!$B$4:$B$6,MATCH(J17,'Thành viên'!$A$4:$A$6,0))="","",INDEX('Thành viên'!$B$4:$B$6,MATCH(J17,'Thành viên'!$A$4:$A$6,0))),"")) -> Phạm Ngọc Trung | N17: Chưa làm
A18: GĐ3-11 | B18: Tổng hợp tài liệu SAD v1.0 | C18: 1. Gộp các phần của 3 người theo cấu trúc: giới thiệu; kiến trúc; thiết kế dữ liệu; thiết kế API; thiết kế giao diện; sơ đồ UML (lớp, tuần tự, hoạt động, trạng thái); thiết kế module AI; bảo mật và bảo vệ dữ liệu cá nhân. 2. Định dạng: chỉ dùng màu mặc định, mục lục tự động, đánh số bảng và hình. 3. Kiểm tra nhất quán: tên thực thể, tên trạng thái, mã use case giống nhau giữa SRS, ERD, sơ đồ lớp và API. 4. Gửi TV1 review và chốt phiên bản v1.0. | D18: Kết quả GĐ3-01 đến GĐ3-10 | E18: SAD_IT_OnSite_v1.0.docx (D6) | F18: Đủ các chương nêu ở bước 1; không có mâu thuẫn tên gọi giữa các tài liệu. | G18: D6 | H18: TV3 | I18: =IF(H18="","",IFERROR(IF(INDEX('Thành viên'!$B$4:$B$6,MATCH(H18,'Thành viên'!$A$4:$A$6,0))="","",INDEX('Thành viên'!$B$4:$B$6,MATCH(H18,'Thành viên'!$A$4:$A$6,0))),"")) -> Nguyễn Văn Thu | J18: TV1 | K18: =IF(J18="","",IFERROR(IF(INDEX('Thành viên'!$B$4:$B$6,MATCH(J18,'Thành viên'!$A$4:$A$6,0))="","",INDEX('Thành viên'!$B$4:$B$6,MATCH(J18,'Thành viên'!$A$4:$A$6,0))),"")) -> Phạm Ngọc Trung | N18: Chưa làm

Sheet GĐ4 Lập trình
A1: GIAI ĐOẠN 4 – LẬP TRÌNH
A2: Hiện thực hệ thống chạy thật theo SRS v1.0 và SAD v1.0. Mỗi công việc làm trên nhánh feature/<mã công việc>, gộp vào develop qua Pull Request có review và có kiểm thử tự động.
A4: Mã CV | B4: Công việc | C4: Mô tả chi tiết (các bước thực hiện) | D4: Đầu vào cần có | E4: Kết quả đầu ra | F4: Tiêu chí hoàn thành | G4: Liên quan (UC / BR / NFR) | H4: Mã TV | I4: Người thực hiện | J4: Mã người review | K4: Người review | L4: Bắt đầu | M4: Hạn | N4: Trạng thái | O4: Ghi chú
A5: ="TV1 – "&'Thành viên'!B4&" – "&'Thành viên'!E4 -> TV1 – Phạm Ngọc Trung – Backend, AI, triển khai
A6: GĐ4-01 | B6: Khung dự án backend và hạ tầng chạy chung | C6: 1. Tạo dự án FastAPI theo cấu trúc lớp đã thiết kế (GĐ3-01); dùng SQLAlchemy 2 và Alembic; tạo migration đầu tiên từ lược đồ GĐ3-02. 2. Cấu hình bằng biến môi trường, có file .env.example. 3. docker-compose chạy cùng lúc: PostgreSQL, backend, frontend. 4. GitHub Actions: chạy kiểm tra mã (ruff) và kiểm thử (pytest) cho mọi Pull Request. 5. Endpoint /health và trang tài liệu API tự động /docs. | D6: SAD v1.0; schema.sql (GĐ3-02) | E6: Thư mục backend/ và infra/ chạy được | F6: Thành viên mới chỉ cần chạy docker compose up là có hệ thống chạy; CI chạy thành công trên Pull Request. | G6: NFR-15, NFR-16 | H6: TV1 | I6: =IF(H6="","",IFERROR(IF(INDEX('Thành viên'!$B$4:$B$6,MATCH(H6,'Thành viên'!$A$4:$A$6,0))="","",INDEX('Thành viên'!$B$4:$B$6,MATCH(H6,'Thành viên'!$A$4:$A$6,0))),"")) -> Phạm Ngọc Trung | J6: TV3 | K6: =IF(J6="","",IFERROR(IF(INDEX('Thành viên'!$B$4:$B$6,MATCH(J6,'Thành viên'!$A$4:$A$6,0))="","",INDEX('Thành viên'!$B$4:$B$6,MATCH(J6,'Thành viên'!$A$4:$A$6,0))),"")) -> Nguyễn Văn Thu | N6: Chưa làm
A7: GĐ4-02 | B7: Đăng ký, đăng nhập và phân quyền | C7: 1. Đăng ký bằng email hoặc số điện thoại kèm đồng ý xử lý dữ liệu cá nhân; đăng nhập; làm mới token; quên mật khẩu qua email. 2. Băm mật khẩu bằng bcrypt hoặc Argon2; khóa tạm khi đăng nhập sai nhiều lần. 3. Phân quyền theo 4 vai trò, một tài khoản có thể giữ nhiều vai trò; kiểm tra quyền ở mọi endpoint. 4. Quản trị viên tạo tài khoản nội bộ, gán vai trò, khóa tài khoản (UC22). 5. Ghi nhật ký hệ thống khi thay đổi phân quyền. 6. Viết kiểm thử tự động cho đăng nhập và phân quyền. | D7: Khung backend (GĐ4-01); openapi.yaml | E7: Module xác thực và phân quyền | F7: Gọi API trái quyền đều bị từ chối (mã 403); không có mật khẩu dạng rõ trong CSDL. | G7: UC01, UC22; NFR-04, NFR-05, NFR-06, NFR-08, NFR-10 | H7: TV1 | I7: =IF(H7="","",IFERROR(IF(INDEX('Thành viên'!$B$4:$B$6,MATCH(H7,'Thành viên'!$A$4:$A$6,0))="","",INDEX('Thành viên'!$B$4:$B$6,MATCH(H7,'Thành viên'!$A$4:$A$6,0))),"")) -> Phạm Ngọc Trung | J7: TV3 | K7: =IF(J7="","",IFERROR(IF(INDEX('Thành viên'!$B$4:$B$6,MATCH(J7,'Thành viên'!$A$4:$A$6,0))="","",INDEX('Thành viên'!$B$4:$B$6,MATCH(J7,'Thành viên'!$A$4:$A$6,0))),"")) -> Nguyễn Văn Thu | N7: Chưa làm
A8: GĐ4-03 | B8: Phiếu yêu cầu và máy trạng thái | C8: 1. API tạo phiếu (UC04): kiểm tra dữ liệu, tải ảnh (tối đa 5, kiểm tra định dạng và dung lượng), lưu đồng ý điều khoản. 2. API danh sách và chi tiết phiếu theo vai trò (UC06): khách chỉ thấy phiếu của mình, kỹ thuật viên chỉ thấy phiếu được giao. 3. Một hàm chuyển trạng thái dùng chung cho toàn hệ thống: chỉ cho phép các chuyển đổi có trong sơ đồ trạng thái, ghi lịch sử trạng thái, phát sự kiện để gửi thông báo. 4. Hủy và đổi lịch hẹn theo BR-03 (UC07). 5. Chống hai người cập nhật cùng lúc bằng cột phiên bản. 6. Viết kiểm thử tự động cho mọi chuyển trạng thái hợp lệ và không hợp lệ. 7. Viết hướng dẫn dùng hàm chuyển trạng thái để TV3 gọi trong module thanh toán, thông báo. | D8: Khung backend (GĐ4-01); sơ đồ trạng thái phiếu | E8: Module phiếu yêu cầu; tài liệu hàm chuyển trạng thái | F8: Chuyển trạng thái sai quy trình luôn bị từ chối; mọi lần chuyển đều có một dòng lịch sử. | G8: UC04, UC06, UC07; BR-03; NFR-08 | H8: TV1 | I8: =IF(H8="","",IFERROR(IF(INDEX('Thành viên'!$B$4:$B$6,MATCH(H8,'Thành viên'!$A$4:$A$6,0))="","",INDEX('Thành viên'!$B$4:$B$6,MATCH(H8,'Thành viên'!$A$4:$A$6,0))),"")) -> Phạm Ngọc Trung | J8: TV3 | K8: =IF(J8="","",IFERROR(IF(INDEX('Thành viên'!$B$4:$B$6,MATCH(J8,'Thành viên'!$A$4:$A$6,0))="","",INDEX('Thành viên'!$B$4:$B$6,MATCH(J8,'Thành viên'!$A$4:$A$6,0))),"")) -> Nguyễn Văn Thu | N8: Chưa làm
A9: GĐ4-04 | B9: Điều phối và phân công kỹ thuật viên | C9: 1. API danh sách phiếu chờ cho điều phối viên, sắp xếp theo mức khẩn và thời gian tạo. 2. Gợi ý kỹ thuật viên theo thứ tự ở BR-05; loại kỹ thuật viên trùng lịch theo BR-04. 3. Phân công, nhận việc, từ chối việc (UC08, UC09). 4. Tác vụ chạy nền tự thu hồi phân công khi kỹ thuật viên quá hạn phản hồi (BR-06) và cảnh báo điều phối viên. 5. Viết kiểm thử tự động cho gợi ý, trùng lịch và quá hạn. | D9: Module phiếu (GĐ4-03); danh mục kỹ thuật viên (GĐ4-12) | E9: Module điều phối | F9: Không thể phân công một kỹ thuật viên vào hai lịch chồng nhau; phân công quá hạn được thu hồi đúng thời hạn cấu hình. | G9: UC08, UC09; BR-04, BR-05, BR-06 | H9: TV1 | I9: =IF(H9="","",IFERROR(IF(INDEX('Thành viên'!$B$4:$B$6,MATCH(H9,'Thành viên'!$A$4:$A$6,0))="","",INDEX('Thành viên'!$B$4:$B$6,MATCH(H9,'Thành viên'!$A$4:$A$6,0))),"")) -> Phạm Ngọc Trung | J9: TV3 | K9: =IF(J9="","",IFERROR(IF(INDEX('Thành viên'!$B$4:$B$6,MATCH(J9,'Thành viên'!$A$4:$A$6,0))="","",INDEX('Thành viên'!$B$4:$B$6,MATCH(J9,'Thành viên'!$A$4:$A$6,0))),"")) -> Nguyễn Văn Thu | N9: Chưa làm
A10: GĐ4-05 | B10: Báo giá, thực hiện và nghiệm thu | C10: 1. Kỹ thuật viên check-in, lập báo giá từ bảng giá và linh kiện; lập báo giá bổ sung khi phát sinh (UC10, UC12). 2. Đơn giá được cố định tại thời điểm lập báo giá (BR-13). 3. Khách duyệt toàn bộ, một phần hoặc từ chối; xác nhận tại chỗ bằng mã gửi qua Telegram hoặc email (UC11). 4. Tải ảnh trước và sau; chỉ được báo hoàn thành khi đủ ảnh (BR-11). 5. Khách nghiệm thu đạt hoặc không đạt kèm lý do (UC13). 6. Viết kiểm thử tự động cho BR-01, BR-02, BR-11, BR-13. | D10: Module phiếu (GĐ4-03); danh mục dịch vụ (GĐ4-12) | E10: Module báo giá và nghiệm thu | F10: Không thể thực hiện hạng mục chưa được duyệt; đổi bảng giá không làm thay đổi báo giá đã lập. | G10: UC10–UC13; BR-01, BR-02, BR-11, BR-13 | H10: TV1 | I10: =IF(H10="","",IFERROR(IF(INDEX('Thành viên'!$B$4:$B$6,MATCH(H10,'Thành viên'!$A$4:$A$6,0))="","",INDEX('Thành viên'!$B$4:$B$6,MATCH(H10,'Thành viên'!$A$4:$A$6,0))),"")) -> Phạm Ngọc Trung | J10: TV3 | K10: =IF(J10="","",IFERROR(IF(INDEX('Thành viên'!$B$4:$B$6,MATCH(J10,'Thành viên'!$A$4:$A$6,0))="","",INDEX('Thành viên'!$B$4:$B$6,MATCH(J10,'Thành viên'!$A$4:$A$6,0))),"")) -> Nguyễn Văn Thu | N10: Chưa làm
A11: GĐ4-06 | B11: Tích hợp AI phân loại sự cố | C11: 1. Gọi Gemini API theo prompt và lược đồ JSON đã thiết kế (GĐ3-04); khóa API lấy từ biến môi trường. 2. Lọc dữ liệu cá nhân trước khi gửi. 3. Quá 10 giây hoặc lỗi: bỏ qua gợi ý, không chặn việc tạo phiếu; JSON sai: gửi lại 1 lần. 4. Ánh xạ loại sự cố sang dịch vụ, giá lấy từ CSDL (BR-09); lưu kết quả và phiên bản prompt. 5. Kiểm thử bằng cách giả lập API trả chậm và trả sai định dạng. | D11: Thiết kế module AI (GĐ3-04); module phiếu (GĐ4-03) | E11: Module AI | F11: Khi Gemini lỗi, khách vẫn tạo được phiếu; dữ liệu gửi đi không chứa số điện thoại, email. | G11: UC05; BR-09; NFR-03, NFR-10, NFR-18 | H11: TV1 | I11: =IF(H11="","",IFERROR(IF(INDEX('Thành viên'!$B$4:$B$6,MATCH(H11,'Thành viên'!$A$4:$A$6,0))="","",INDEX('Thành viên'!$B$4:$B$6,MATCH(H11,'Thành viên'!$A$4:$A$6,0))),"")) -> Phạm Ngọc Trung | J11: TV3 | K11: =IF(J11="","",IFERROR(IF(INDEX('Thành viên'!$B$4:$B$6,MATCH(J11,'Thành viên'!$A$4:$A$6,0))="","",INDEX('Thành viên'!$B$4:$B$6,MATCH(J11,'Thành viên'!$A$4:$A$6,0))),"")) -> Nguyễn Văn Thu | N11: Chưa làm
A12: GĐ4-07 | B12: Bản demo và báo cáo giữa kỳ | C12: 1. Chuẩn bị dữ liệu mẫu và kịch bản demo luồng: khách tạo yêu cầu → AI phân loại → điều phối viên phân công → kỹ thuật viên báo giá → khách duyệt. 2. Triển khai bản chạy thử lên máy chủ để demo không phụ thuộc máy cá nhân. 3. Làm slide báo cáo giữa kỳ: tiến độ theo file này, tài liệu đã hoàn thành, phần đã chạy được, kế hoạch tiếp theo. 4. Tổng hợp bộ kết quả giữa kỳ (SRS v1.0, SAD v1.0, lược đồ CSDL, link repository) và nộp. | D12: SRS v1.0; SAD v1.0; các module đã gộp vào develop | E12: Bản demo giữa kỳ (D8), slide, bộ kết quả giữa kỳ đã nộp | F12: Luồng demo chạy liền mạch trên bản triển khai thử. | G12: D5, D6, D7, D8 | H12: TV1 | I12: =IF(H12="","",IFERROR(IF(INDEX('Thành viên'!$B$4:$B$6,MATCH(H12,'Thành viên'!$A$4:$A$6,0))="","",INDEX('Thành viên'!$B$4:$B$6,MATCH(H12,'Thành viên'!$A$4:$A$6,0))),"")) -> Phạm Ngọc Trung | K12: =IF(J12="","",IFERROR(IF(INDEX('Thành viên'!$B$4:$B$6,MATCH(J12,'Thành viên'!$A$4:$A$6,0))="","",INDEX('Thành viên'!$B$4:$B$6,MATCH(J12,'Thành viên'!$A$4:$A$6,0))),"")) | N12: Chưa làm
A13: ="TV2 – "&'Thành viên'!B5&" – "&'Thành viên'!E5 -> TV2 – Trần Quốc Anh Hoàng – Frontend, giao diện
A14: GĐ4-08 | B14: Khung giao diện và đăng nhập | C14: 1. Tạo dự án React (Vite) theo cấu trúc đã thiết kế (GĐ3-07). 2. Lớp gọi API dùng chung: gắn token, tự làm mới token, xử lý lỗi chung. 3. Điều hướng theo vai trò sau khi đăng nhập; chặn trang không đúng vai trò. 4. Màn hình đăng ký, đăng nhập, quên mật khẩu, hồ sơ cá nhân. 5. Bộ thành phần giao diện dùng chung theo mockup (GĐ3-06) để cả nhóm dùng. | D14: Mockup (GĐ3-06); openapi.yaml (GĐ3-03) | E14: Thư mục frontend/ chạy được, đăng nhập được với 4 vai trò | F14: Mỗi vai trò đăng nhập vào đúng trang của mình; giao diện hiển thị tốt ở chiều rộng 360 px. | G14: UC01, UC02; NFR-05, NFR-11 | H14: TV2 | I14: =IF(H14="","",IFERROR(IF(INDEX('Thành viên'!$B$4:$B$6,MATCH(H14,'Thành viên'!$A$4:$A$6,0))="","",INDEX('Thành viên'!$B$4:$B$6,MATCH(H14,'Thành viên'!$A$4:$A$6,0))),"")) -> Trần Quốc Anh Hoàng | J14: TV1 | K14: =IF(J14="","",IFERROR(IF(INDEX('Thành viên'!$B$4:$B$6,MATCH(J14,'Thành viên'!$A$4:$A$6,0))="","",INDEX('Thành viên'!$B$4:$B$6,MATCH(J14,'Thành viên'!$A$4:$A$6,0))),"")) -> Phạm Ngọc Trung | N14: Chưa làm
A15: GĐ4-09 | B15: Giao diện khách hàng | C15: 1. Trang chủ và bảng giá (UC03); quản lý thiết bị (UC02). 2. Tạo yêu cầu nhiều bước: chọn thiết bị → mô tả và ảnh → gợi ý AI → địa chỉ, khung giờ → phí khảo sát, chính sách hủy, đồng ý điều khoản → gửi (UC04, UC05). 3. Danh sách và chi tiết phiếu với dòng thời gian trạng thái; hủy hoặc đổi lịch (UC06, UC07). 4. Xem và duyệt báo giá; nghiệm thu (UC11, UC13). 5. Thanh toán hiển thị mã VietQR (UC14); bảo hành; đánh giá (UC15, UC16). | D15: Khung giao diện (GĐ4-08); API tương ứng | E15: Toàn bộ màn hình phía khách hàng | F15: Một khách mới tạo được yêu cầu trong không quá 3 phút; mọi màn hình có trạng thái đang tải, không có dữ liệu, lỗi. | G15: UC02–UC07, UC11, UC13–UC16; NFR-11, NFR-12 | H15: TV2 | I15: =IF(H15="","",IFERROR(IF(INDEX('Thành viên'!$B$4:$B$6,MATCH(H15,'Thành viên'!$A$4:$A$6,0))="","",INDEX('Thành viên'!$B$4:$B$6,MATCH(H15,'Thành viên'!$A$4:$A$6,0))),"")) -> Trần Quốc Anh Hoàng | J15: TV1 | K15: =IF(J15="","",IFERROR(IF(INDEX('Thành viên'!$B$4:$B$6,MATCH(J15,'Thành viên'!$A$4:$A$6,0))="","",INDEX('Thành viên'!$B$4:$B$6,MATCH(J15,'Thành viên'!$A$4:$A$6,0))),"")) -> Phạm Ngọc Trung | N15: Chưa làm
A16: GĐ4-10 | B16: Giao diện kỹ thuật viên trên điện thoại | C16: 1. Lịch việc trong ngày; nhận hoặc từ chối việc, hiển thị thời gian còn lại để phản hồi (UC09). 2. Chi tiết việc: địa chỉ, mô tả, ảnh, gợi ý AI; nút check-in. 3. Lập báo giá từ bảng giá và linh kiện; báo giá bổ sung (UC10). 4. Cập nhật tiến độ, chụp hoặc tải ảnh trước và sau, báo hoàn thành (UC12). 5. Xác nhận đã thu tiền mặt (UC14). | D16: Khung giao diện (GĐ4-08); API tương ứng | E16: Toàn bộ màn hình phía kỹ thuật viên | F16: Thực hiện trọn một việc từ nhận việc tới thu tiền chỉ bằng điện thoại. | G16: UC09, UC10, UC12, UC14; BR-06, BR-11; NFR-11 | H16: TV2 | I16: =IF(H16="","",IFERROR(IF(INDEX('Thành viên'!$B$4:$B$6,MATCH(H16,'Thành viên'!$A$4:$A$6,0))="","",INDEX('Thành viên'!$B$4:$B$6,MATCH(H16,'Thành viên'!$A$4:$A$6,0))),"")) -> Trần Quốc Anh Hoàng | J16: TV1 | K16: =IF(J16="","",IFERROR(IF(INDEX('Thành viên'!$B$4:$B$6,MATCH(J16,'Thành viên'!$A$4:$A$6,0))="","",INDEX('Thành viên'!$B$4:$B$6,MATCH(J16,'Thành viên'!$A$4:$A$6,0))),"")) -> Phạm Ngọc Trung | N16: Chưa làm
