Workbook

Sheet Thông tin
B2: WBS – HỆ THỐNG QUẢN LÝ DỊCH VỤ HỖ TRỢ IT TẬN NƠI (IT ONSITE)
B3: Học phần: Đồ án thực tế công nghệ phần mềm – Mã HP 010412203902 – HK1 2026–2027
B5: THÀNH VIÊN NHÓM
B6: Mã | C6: Họ và tên | D6: MSSV | E6: Vai trò chính
B7: TV1 | C7: Phạm Ngọc Trung | D7: 080205000925 | E7: Nhóm trưởng – Backend, AI, DevOps
B8: TV2 | C8: Trần Quốc Anh Hoàng | D8: 079205045903 | E8: Frontend, UI/UX
B9: TV3 | C9: Nguyễn Văn Thu | D9: 22H1120025 | E9: Phân tích nghiệp vụ, kiểm thử, tài liệu

Sheet WBS
A1: BẢNG PHÂN RÃ CÔNG VIỆC (WBS) – IT ONSITE
L2: Từ ngày | M2: 46307 | N2: 46314 | O2: 46321 | P2: 46328 | Q2: 46335 | R2: 46342 | S2: 46349 | T2: 46356 | U2: 46363 | V2: 46370 | W2: 46377 | X2: 46384 | Y2: 46391 | Z2: 46398
L3: Đến ngày | M3: 46313 | N3: 46320 | O3: 46327 | P3: 46334 | Q3: 46341 | R3: 46348 | S3: 46355 | T3: 46362 | U3: 46369 | V3: 46376 | W3: 46383 | X3: 46390 | Y3: 46397 | Z3: 46404
A4: Mã WBS | B4: Hạng mục công việc | C4: Kết quả đầu ra | D4: Phụ trách | E4: Họ tên phụ trách | F4: Hỗ trợ | G4: Bắt đầu | H4: Kết thúc | I4: Số ngày | J4: Ước lượng (giờ) | K4: Phụ thuộc | L4: Trạng thái | M4: T2 | N4: T3 | O4: T4 | P4: T5 | Q4: T6 | R4: T7 | S4: T8 | T4: T9 | U4: T10 | V4: T11 | W4: T12 | X4: T13 | Y4: T14 | Z4: T15
A5: 1 | B5: Quản lý dự án | G5: =MIN(G6:G9) -> 46308 | H5: =MAX(H6:H9) -> 46404 | I5: =H5-G5+1 -> 97 | J5: =SUM(J6:J9) -> 23 | M5: =IF(AND($G5<=M$3,$H5>=M$2),1,"") -> 1 | N5: =IF(AND($G5<=N$3,$H5>=N$2),1,"") -> 1 | O5: =IF(AND($G5<=O$3,$H5>=O$2),1,"") -> 1 | P5: =IF(AND($G5<=P$3,$H5>=P$2),1,"") -> 1 | Q5: =IF(AND($G5<=Q$3,$H5>=Q$2),1,"") -> 1 | R5: =IF(AND($G5<=R$3,$H5>=R$2),1,"") -> 1 | S5: =IF(AND($G5<=S$3,$H5>=S$2),1,"") -> 1 | T5: =IF(AND($G5<=T$3,$H5>=T$2),1,"") -> 1 | ... Z5: =IF(AND($G5<=Z$3,$H5>=Z$2),1,"") -> 1
A6: 1.1 | B6: Lập kế hoạch, WBS và phân công | C6: WBS & kế hoạch (D3) | D6: TV1 | E6: =IFERROR(IF(INDEX('Thông tin'!$C$7:$C$9,MATCH(D6,'Thông tin'!$B$7:$B$9,0))="","",INDEX('Thông tin'!$C$7:$C$9,MATCH(D6,'Thông tin'!$B$7:$B$9,0))),"") -> Phạm Ngọc Trung | F6: TV2, TV3 | G6: 46308 | H6: 46312 | I6: =H6-G6+1 -> 5 | J6: 6 | L6: Đang thực hiện | M6: =IF(AND($G6<=M$3,$H6>=M$2),1,"") -> 1 | N6: =IF(AND($G6<=N$3,$H6>=N$2),1,"") | O6: =IF(AND($G6<=O$3,$H6>=O$2),1,"") | P6: =IF(AND($G6<=P$3,$H6>=P$2),1,"") | Q6: =IF(AND($G6<=Q$3,$H6>=Q$2),1,"") | R6: =IF(AND($G6<=R$3,$H6>=R$2),1,"") | S6: =IF(AND($G6<=S$3,$H6>=S$2),1,"") | T6: =IF(AND($G6<=T$3,$H6>=T$2),1,"") | ... Z6: =IF(AND($G6<=Z$3,$H6>=Z$2),1,"")
A7: 1.2 | B7: Thiết lập workspace GitHub: repo, nhánh, board, CI khung | C7: Workspace Git (D4) | D7: TV1 | E7: =IFERROR(IF(INDEX('Thông tin'!$C$7:$C$9,MATCH(D7,'Thông tin'!$B$7:$B$9,0))="","",INDEX('Thông tin'!$C$7:$C$9,MATCH(D7,'Thông tin'!$B$7:$B$9,0))),"") -> Phạm Ngọc Trung | G7: 46309 | H7: 46312 | I7: =H7-G7+1 -> 4 | J7: 5 | L7: Đang thực hiện | M7: =IF(AND($G7<=M$3,$H7>=M$2),1,"") -> 1 | N7: =IF(AND($G7<=N$3,$H7>=N$2),1,"") | O7: =IF(AND($G7<=O$3,$H7>=O$2),1,"") | P7: =IF(AND($G7<=P$3,$H7>=P$2),1,"") | Q7: =IF(AND($G7<=Q$3,$H7>=Q$2),1,"") | R7: =IF(AND($G7<=R$3,$H7>=R$2),1,"") | S7: =IF(AND($G7<=S$3,$H7>=S$2),1,"") | T7: =IF(AND($G7<=T$3,$H7>=T$2),1,"") | ... Z7: =IF(AND($G7<=Z$3,$H7>=Z$2),1,"")
A8: 1.3 | B8: Chủ trì họp nhóm hằng tuần, báo cáo tiến độ với giảng viên | C8: Biên bản họp | D8: TV1 | E8: =IFERROR(IF(INDEX('Thông tin'!$C$7:$C$9,MATCH(D8,'Thông tin'!$B$7:$B$9,0))="","",INDEX('Thông tin'!$C$7:$C$9,MATCH(D8,'Thông tin'!$B$7:$B$9,0))),"") -> Phạm Ngọc Trung | F8: TV2, TV3 | G8: 46314 | H8: 46404 | I8: =H8-G8+1 -> 91 | J8: 8 | L8: Chưa bắt đầu | M8: =IF(AND($G8<=M$3,$H8>=M$2),1,"") | N8: =IF(AND($G8<=N$3,$H8>=N$2),1,"") -> 1 | O8: =IF(AND($G8<=O$3,$H8>=O$2),1,"") -> 1 | P8: =IF(AND($G8<=P$3,$H8>=P$2),1,"") -> 1 | Q8: =IF(AND($G8<=Q$3,$H8>=Q$2),1,"") -> 1 | R8: =IF(AND($G8<=R$3,$H8>=R$2),1,"") -> 1 | S8: =IF(AND($G8<=S$3,$H8>=S$2),1,"") -> 1 | T8: =IF(AND($G8<=T$3,$H8>=T$2),1,"") -> 1 | ... Z8: =IF(AND($G8<=Z$3,$H8>=Z$2),1,"") -> 1
A9: 1.4 | B9: Theo dõi rủi ro, điều chỉnh kế hoạch | C9: Bảng rủi ro | D9: TV1 | E9: =IFERROR(IF(INDEX('Thông tin'!$C$7:$C$9,MATCH(D9,'Thông tin'!$B$7:$B$9,0))="","",INDEX('Thông tin'!$C$7:$C$9,MATCH(D9,'Thông tin'!$B$7:$B$9,0))),"") -> Phạm Ngọc Trung | G9: 46314 | H9: 46397 | I9: =H9-G9+1 -> 84 | J9: 4 | L9: Chưa bắt đầu | M9: =IF(AND($G9<=M$3,$H9>=M$2),1,"") | N9: =IF(AND($G9<=N$3,$H9>=N$2),1,"") -> 1 | O9: =IF(AND($G9<=O$3,$H9>=O$2),1,"") -> 1 | P9: =IF(AND($G9<=P$3,$H9>=P$2),1,"") -> 1 | Q9: =IF(AND($G9<=Q$3,$H9>=Q$2),1,"") -> 1 | R9: =IF(AND($G9<=R$3,$H9>=R$2),1,"") -> 1 | S9: =IF(AND($G9<=S$3,$H9>=S$2),1,"") -> 1 | T9: =IF(AND($G9<=T$3,$H9>=T$2),1,"") -> 1 | ... Z9: =IF(AND($G9<=Z$3,$H9>=Z$2),1,"")
A10: 2 | B10: Khảo sát và phân tích yêu cầu | G10: =MIN(G11:G16) -> 46307 | H10: =MAX(H11:H16) -> 46334 | I10: =H10-G10+1 -> 28 | J10: =SUM(J11:J16) -> 46 | M10: =IF(AND($G10<=M$3,$H10>=M$2),1,"") -> 1 | N10: =IF(AND($G10<=N$3,$H10>=N$2),1,"") -> 1 | O10: =IF(AND($G10<=O$3,$H10>=O$2),1,"") -> 1 | P10: =IF(AND($G10<=P$3,$H10>=P$2),1,"") -> 1 | Q10: =IF(AND($G10<=Q$3,$H10>=Q$2),1,"") | R10: =IF(AND($G10<=R$3,$H10>=R$2),1,"") | S10: =IF(AND($G10<=S$3,$H10>=S$2),1,"") | T10: =IF(AND($G10<=T$3,$H10>=T$2),1,"") | ... Z10: =IF(AND($G10<=Z$3,$H10>=Z$2),1,"")
A11: 2.1 | B11: Phỏng vấn chủ dịch vụ, phân tích quy trình nghiệp vụ | C11: Ghi chép phỏng vấn | D11: TV3 | E11: =IFERROR(IF(INDEX('Thông tin'!$C$7:$C$9,MATCH(D11,'Thông tin'!$B$7:$B$9,0))="","",INDEX('Thông tin'!$C$7:$C$9,MATCH(D11,'Thông tin'!$B$7:$B$9,0))),"") -> Nguyễn Văn Thu | F11: TV1 | G11: 46307 | H11: 46310 | I11: =H11-G11+1 -> 4 | J11: 4 | L11: Hoàn thành | M11: =IF(AND($G11<=M$3,$H11>=M$2),1,"") -> 1 | N11: =IF(AND($G11<=N$3,$H11>=N$2),1,"") | O11: =IF(AND($G11<=O$3,$H11>=O$2),1,"") | P11: =IF(AND($G11<=P$3,$H11>=P$2),1,"") | Q11: =IF(AND($G11<=Q$3,$H11>=Q$2),1,"") | R11: =IF(AND($G11<=R$3,$H11>=R$2),1,"") | S11: =IF(AND($G11<=S$3,$H11>=S$2),1,"") | T11: =IF(AND($G11<=T$3,$H11>=T$2),1,"") | ... Z11: =IF(AND($G11<=Z$3,$H11>=Z$2),1,"")
A12: 2.2 | B12: Xác định actor, use case, quy tắc nghiệp vụ | C12: Danh sách UC, BR | D12: TV3 | E12: =IFERROR(IF(INDEX('Thông tin'!$C$7:$C$9,MATCH(D12,'Thông tin'!$B$7:$B$9,0))="","",INDEX('Thông tin'!$C$7:$C$9,MATCH(D12,'Thông tin'!$B$7:$B$9,0))),"") -> Nguyễn Văn Thu | F12: TV1 | G12: 46308 | H12: 46311 | I12: =H12-G12+1 -> 4 | J12: 6 | K12: 2.1 | L12: Đang thực hiện | M12: =IF(AND($G12<=M$3,$H12>=M$2),1,"") -> 1 | N12: =IF(AND($G12<=N$3,$H12>=N$2),1,"") | O12: =IF(AND($G12<=O$3,$H12>=O$2),1,"") | P12: =IF(AND($G12<=P$3,$H12>=P$2),1,"") | Q12: =IF(AND($G12<=Q$3,$H12>=Q$2),1,"") | R12: =IF(AND($G12<=R$3,$H12>=R$2),1,"") | S12: =IF(AND($G12<=S$3,$H12>=S$2),1,"") | T12: =IF(AND($G12<=T$3,$H12>=T$2),1,"") | ... Z12: =IF(AND($G12<=Z$3,$H12>=Z$2),1,"")
A13: 2.3 | B13: Viết SRS sơ bộ v0.1, sơ đồ use case và trạng thái phiếu | C13: SRS v0.1 (D2) | D13: TV3 | E13: =IFERROR(IF(INDEX('Thông tin'!$C$7:$C$9,MATCH(D13,'Thông tin'!$B$7:$B$9,0))="","",INDEX('Thông tin'!$C$7:$C$9,MATCH(D13,'Thông tin'!$B$7:$B$9,0))),"") -> Nguyễn Văn Thu | F13: TV1, TV2 | G13: 46309 | H13: 46312 | I13: =H13-G13+1 -> 4 | J13: 10 | K13: 2.2 | L13: Đang thực hiện | M13: =IF(AND($G13<=M$3,$H13>=M$2),1,"") -> 1 | N13: =IF(AND($G13<=N$3,$H13>=N$2),1,"") | O13: =IF(AND($G13<=O$3,$H13>=O$2),1,"") | P13: =IF(AND($G13<=P$3,$H13>=P$2),1,"") | Q13: =IF(AND($G13<=Q$3,$H13>=Q$2),1,"") | R13: =IF(AND($G13<=R$3,$H13>=R$2),1,"") | S13: =IF(AND($G13<=S$3,$H13>=S$2),1,"") | T13: =IF(AND($G13<=T$3,$H13>=T$2),1,"") | ... Z13: =IF(AND($G13<=Z$3,$H13>=Z$2),1,"")
A14: 2.4 | B14: Khảo sát người dùng tiềm năng (15–20 người) | C14: Kết quả khảo sát | D14: TV3 | E14: =IFERROR(IF(INDEX('Thông tin'!$C$7:$C$9,MATCH(D14,'Thông tin'!$B$7:$B$9,0))="","",INDEX('Thông tin'!$C$7:$C$9,MATCH(D14,'Thông tin'!$B$7:$B$9,0))),"") -> Nguyễn Văn Thu | F14: TV2 | G14: 46314 | H14: 46320 | I14: =H14-G14+1 -> 7 | J14: 6 | K14: 2.3 | L14: Chưa bắt đầu | M14: =IF(AND($G14<=M$3,$H14>=M$2),1,"") | N14: =IF(AND($G14<=N$3,$H14>=N$2),1,"") -> 1 | O14: =IF(AND($G14<=O$3,$H14>=O$2),1,"") | P14: =IF(AND($G14<=P$3,$H14>=P$2),1,"") | Q14: =IF(AND($G14<=Q$3,$H14>=Q$2),1,"") | R14: =IF(AND($G14<=R$3,$H14>=R$2),1,"") | S14: =IF(AND($G14<=S$3,$H14>=S$2),1,"") | T14: =IF(AND($G14<=T$3,$H14>=T$2),1,"") | ... Z14: =IF(AND($G14<=Z$3,$H14>=Z$2),1,"")
A15: 2.5 | B15: Đặc tả chi tiết toàn bộ use case | C15: Đặc tả UC01–UC23 | D15: TV3 | E15: =IFERROR(IF(INDEX('Thông tin'!$C$7:$C$9,MATCH(D15,'Thông tin'!$B$7:$B$9,0))="","",INDEX('Thông tin'!$C$7:$C$9,MATCH(D15,'Thông tin'!$B$7:$B$9,0))),"") -> Nguyễn Văn Thu | F15: TV1 | G15: 46314 | H15: 46327 | I15: =H15-G15+1 -> 14 | J15: 14 | K15: 2.3 | L15: Chưa bắt đầu | M15: =IF(AND($G15<=M$3,$H15>=M$2),1,"") | N15: =IF(AND($G15<=N$3,$H15>=N$2),1,"") -> 1 | O15: =IF(AND($G15<=O$3,$H15>=O$2),1,"") -> 1 | P15: =IF(AND($G15<=P$3,$H15>=P$2),1,"") | Q15: =IF(AND($G15<=Q$3,$H15>=Q$2),1,"") | R15: =IF(AND($G15<=R$3,$H15>=R$2),1,"") | S15: =IF(AND($G15<=S$3,$H15>=S$2),1,"") | T15: =IF(AND($G15<=T$3,$H15>=T$2),1,"") | ... Z15: =IF(AND($G15<=Z$3,$H15>=Z$2),1,"")
A16: 2.6 | B16: Hoàn thiện SRS v1.0 | C16: SRS v1.0 (D5) | D16: TV3 | E16: =IFERROR(IF(INDEX('Thông tin'!$C$7:$C$9,MATCH(D16,'Thông tin'!$B$7:$B$9,0))="","",INDEX('Thông tin'!$C$7:$C$9,MATCH(D16,'Thông tin'!$B$7:$B$9,0))),"") -> Nguyễn Văn Thu | G16: 46328 | H16: 46334 | I16: =H16-G16+1 -> 7 | J16: 6 | K16: 2.4, 2.5 | L16: Chưa bắt đầu | M16: =IF(AND($G16<=M$3,$H16>=M$2),1,"") | N16: =IF(AND($G16<=N$3,$H16>=N$2),1,"") | O16: =IF(AND($G16<=O$3,$H16>=O$2),1,"") | P16: =IF(AND($G16<=P$3,$H16>=P$2),1,"") -> 1 | Q16: =IF(AND($G16<=Q$3,$H16>=Q$2),1,"") | R16: =IF(AND($G16<=R$3,$H16>=R$2),1,"") | S16: =IF(AND($G16<=S$3,$H16>=S$2),1,"") | T16: =IF(AND($G16<=T$3,$H16>=T$2),1,"") | ... Z16: =IF(AND($G16<=Z$3,$H16>=Z$2),1,"")
A17: 3 | B17: Thiết kế hệ thống (SAD) | G17: =MIN(G18:G24) -> 46314 | H17: =MAX(H18:H24) -> 46348 | I17: =H17-G17+1 -> 35 | J17: =SUM(J18:J24) -> 66 | M17: =IF(AND($G17<=M$3,$H17>=M$2),1,"") | N17: =IF(AND($G17<=N$3,$H17>=N$2),1,"") -> 1 | O17: =IF(AND($G17<=O$3,$H17>=O$2),1,"") -> 1 | P17: =IF(AND($G17<=P$3,$H17>=P$2),1,"") -> 1 | Q17: =IF(AND($G17<=Q$3,$H17>=Q$2),1,"") -> 1 | R17: =IF(AND($G17<=R$3,$H17>=R$2),1,"") -> 1 | S17: =IF(AND($G17<=S$3,$H17>=S$2),1,"") | T17: =IF(AND($G17<=T$3,$H17>=T$2),1,"") | ... Z17: =IF(AND($G17<=Z$3,$H17>=Z$2),1,"")
A18: 3.1 | B18: Kiến trúc tổng thể, lựa chọn công nghệ | C18: Sơ đồ kiến trúc | D18: TV1 | E18: =IFERROR(IF(INDEX('Thông tin'!$C$7:$C$9,MATCH(D18,'Thông tin'!$B$7:$B$9,0))="","",INDEX('Thông tin'!$C$7:$C$9,MATCH(D18,'Thông tin'!$B$7:$B$9,0))),"") -> Phạm Ngọc Trung | G18: 46314 | H18: 46320 | I18: =H18-G18+1 -> 7 | J18: 6 | K18: 2.3 | L18: Chưa bắt đầu | M18: =IF(AND($G18<=M$3,$H18>=M$2),1,"") | N18: =IF(AND($G18<=N$3,$H18>=N$2),1,"") -> 1 | O18: =IF(AND($G18<=O$3,$H18>=O$2),1,"") | P18: =IF(AND($G18<=P$3,$H18>=P$2),1,"") | Q18: =IF(AND($G18<=Q$3,$H18>=Q$2),1,"") | R18: =IF(AND($G18<=R$3,$H18>=R$2),1,"") | S18: =IF(AND($G18<=S$3,$H18>=S$2),1,"") | T18: =IF(AND($G18<=T$3,$H18>=T$2),1,"") | ... Z18: =IF(AND($G18<=Z$3,$H18>=Z$2),1,"")
A19: 3.2 | B19: Thiết kế CSDL: ERD, lược đồ, migration đầu tiên | C19: Lược đồ CSDL (D7) | D19: TV1 | E19: =IFERROR(IF(INDEX('Thông tin'!$C$7:$C$9,MATCH(D19,'Thông tin'!$B$7:$B$9,0))="","",INDEX('Thông tin'!$C$7:$C$9,MATCH(D19,'Thông tin'!$B$7:$B$9,0))),"") -> Phạm Ngọc Trung | F19: TV3 | G19: 46314 | H19: 46327 | I19: =H19-G19+1 -> 14 | J19: 10 | K19: 2.3 | L19: Chưa bắt đầu | M19: =IF(AND($G19<=M$3,$H19>=M$2),1,"") | N19: =IF(AND($G19<=N$3,$H19>=N$2),1,"") -> 1 | O19: =IF(AND($G19<=O$3,$H19>=O$2),1,"") -> 1 | P19: =IF(AND($G19<=P$3,$H19>=P$2),1,"") | Q19: =IF(AND($G19<=Q$3,$H19>=Q$2),1,"") | R19: =IF(AND($G19<=R$3,$H19>=R$2),1,"") | S19: =IF(AND($G19<=S$3,$H19>=S$2),1,"") | T19: =IF(AND($G19<=T$3,$H19>=T$2),1,"") | ... Z19: =IF(AND($G19<=Z$3,$H19>=Z$2),1,"")
A20: 3.3 | B20: Sơ đồ UML: lớp, tuần tự, hoạt động | C20: Bộ sơ đồ UML | D20: TV3 | E20: =IFERROR(IF(INDEX('Thông tin'!$C$7:$C$9,MATCH(D20,'Thông tin'!$B$7:$B$9,0))="","",INDEX('Thông tin'!$C$7:$C$9,MATCH(D20,'Thông tin'!$B$7:$B$9,0))),"") -> Nguyễn Văn Thu | F20: TV1 | G20: 46321 | H20: 46334 | I20: =H20-G20+1 -> 14 | J20: 12 | K20: 2.5 | L20: Chưa bắt đầu | M20: =IF(AND($G20<=M$3,$H20>=M$2),1,"") | N20: =IF(AND($G20<=N$3,$H20>=N$2),1,"") | O20: =IF(AND($G20<=O$3,$H20>=O$2),1,"") -> 1 | P20: =IF(AND($G20<=P$3,$H20>=P$2),1,"") -> 1 | Q20: =IF(AND($G20<=Q$3,$H20>=Q$2),1,"") | R20: =IF(AND($G20<=R$3,$H20>=R$2),1,"") | S20: =IF(AND($G20<=S$3,$H20>=S$2),1,"") | T20: =IF(AND($G20<=T$3,$H20>=T$2),1,"") | ... Z20: =IF(AND($G20<=Z$3,$H20>=Z$2),1,"")
A21: 3.4 | B21: Thiết kế API (OpenAPI) | C21: Đặc tả API | D21: TV1 | E21: =IFERROR(IF(INDEX('Thông tin'!$C$7:$C$9,MATCH(D21,'Thông tin'!$B$7:$B$9,0))="","",INDEX('Thông tin'!$C$7:$C$9,MATCH(D21,'Thông tin'!$B$7:$B$9,0))),"") -> Phạm Ngọc Trung | F21: TV2 | G21: 46321 | H21: 46327 | I21: =H21-G21+1 -> 7 | J21: 6 | K21: 3.2 | L21: Chưa bắt đầu | M21: =IF(AND($G21<=M$3,$H21>=M$2),1,"") | N21: =IF(AND($G21<=N$3,$H21>=N$2),1,"") | O21: =IF(AND($G21<=O$3,$H21>=O$2),1,"") -> 1 | P21: =IF(AND($G21<=P$3,$H21>=P$2),1,"") | Q21: =IF(AND($G21<=Q$3,$H21>=Q$2),1,"") | R21: =IF(AND($G21<=R$3,$H21>=R$2),1,"") | S21: =IF(AND($G21<=S$3,$H21>=S$2),1,"") | T21: =IF(AND($G21<=T$3,$H21>=T$2),1,"") | ... Z21: =IF(AND($G21<=Z$3,$H21>=Z$2),1,"")
A22: 3.5 | B22: Thiết kế UI/UX: wireframe, mockup Figma | C22: Wireframe, mockup | D22: TV2 | E22: =IFERROR(IF(INDEX('Thông tin'!$C$7:$C$9,MATCH(D22,'Thông tin'!$B$7:$B$9,0))="","",INDEX('Thông tin'!$C$7:$C$9,MATCH(D22,'Thông tin'!$B$7:$B$9,0))),"") -> Trần Quốc Anh Hoàng | F22: TV3 | G22: 46314 | H22: 46334 | I22: =H22-G22+1 -> 21 | J22: 16 | K22: 2.3 | L22: Chưa bắt đầu | M22: =IF(AND($G22<=M$3,$H22>=M$2),1,"") | N22: =IF(AND($G22<=N$3,$H22>=N$2),1,"") -> 1 | O22: =IF(AND($G22<=O$3,$H22>=O$2),1,"") -> 1 | P22: =IF(AND($G22<=P$3,$H22>=P$2),1,"") -> 1 | Q22: =IF(AND($G22<=Q$3,$H22>=Q$2),1,"") | R22: =IF(AND($G22<=R$3,$H22>=R$2),1,"") | S22: =IF(AND($G22<=S$3,$H22>=S$2),1,"") | T22: =IF(AND($G22<=T$3,$H22>=T$2),1,"") | ... Z22: =IF(AND($G22<=Z$3,$H22>=Z$2),1,"")
A23: 3.6 | B23: Thiết kế module AI: danh mục sự cố, prompt, bộ dữ liệu kiểm thử | C23: Thiết kế AI, bộ test | D23: TV1 | E23: =IFERROR(IF(INDEX('Thông tin'!$C$7:$C$9,MATCH(D23,'Thông tin'!$B$7:$B$9,0))="","",INDEX('Thông tin'!$C$7:$C$9,MATCH(D23,'Thông tin'!$B$7:$B$9,0))),"") -> Phạm Ngọc Trung | F23: TV3 | G23: 46321 | H23: 46334 | I23: =H23-G23+1 -> 14 | J23: 8 | K23: 2.5 | L23: Chưa bắt đầu | M23: =IF(AND($G23<=M$3,$H23>=M$2),1,"") | N23: =IF(AND($G23<=N$3,$H23>=N$2),1,"") | O23: =IF(AND($G23<=O$3,$H23>=O$2),1,"") -> 1 | P23: =IF(AND($G23<=P$3,$H23>=P$2),1,"") -> 1 | Q23: =IF(AND($G23<=Q$3,$H23>=Q$2),1,"") | R23: =IF(AND($G23<=R$3,$H23>=R$2),1,"") | S23: =IF(AND($G23<=S$3,$H23>=S$2),1,"") | T23: =IF(AND($G23<=T$3,$H23>=T$2),1,"") | ... Z23: =IF(AND($G23<=Z$3,$H23>=Z$2),1,"")
A24: 3.7 | B24: Hoàn thiện tài liệu SAD | C24: SAD (D6) | D24: TV3 | E24: =IFERROR(IF(INDEX('Thông tin'!$C$7:$C$9,MATCH(D24,'Thông tin'!$B$7:$B$9,0))="","",INDEX('Thông tin'!$C$7:$C$9,MATCH(D24,'Thông tin'!$B$7:$B$9,0))),"") -> Nguyễn Văn Thu | F24: TV1, TV2 | G24: 46335 | H24: 46348 | I24: =H24-G24+1 -> 14 | J24: 8 | K24: 3.1–3.6 | L24: Chưa bắt đầu | M24: =IF(AND($G24<=M$3,$H24>=M$2),1,"") | N24: =IF(AND($G24<=N$3,$H24>=N$2),1,"") | O24: =IF(AND($G24<=O$3,$H24>=O$2),1,"") | P24: =IF(AND($G24<=P$3,$H24>=P$2),1,"") | Q24: =IF(AND($G24<=Q$3,$H24>=Q$2),1,"") -> 1 | R24: =IF(AND($G24<=R$3,$H24>=R$2),1,"") -> 1 | S24: =IF(AND($G24<=S$3,$H24>=S$2),1,"") | T24: =IF(AND($G24<=T$3,$H24>=T$2),1,"") | ... Z24: =IF(AND($G24<=Z$3,$H24>=Z$2),1,"")
A25: 4 | B25: Hiện thực phần mềm | G25: =MIN(G26:G40) -> 46328 | H25: =MAX(H26:H40) -> 46383 | I25: =H25-G25+1 -> 56 | J25: =SUM(J26:J40) -> 194 | M25: =IF(AND($G25<=M$3,$H25>=M$2),1,"") | N25: =IF(AND($G25<=N$3,$H25>=N$2),1,"") | O25: =IF(AND($G25<=O$3,$H25>=O$2),1,"") | P25: =IF(AND($G25<=P$3,$H25>=P$2),1,"") -> 1 | Q25: =IF(AND($G25<=Q$3,$H25>=Q$2),1,"") -> 1 | R25: =IF(AND($G25<=R$3,$H25>=R$2),1,"") -> 1 | S25: =IF(AND($G25<=S$3,$H25>=S$2),1,"") -> 1 | T25: =IF(AND($G25<=T$3,$H25>=T$2),1,"") -> 1 | ... Z25: =IF(AND($G25<=Z$3,$H25>=Z$2),1,"")
A26: 4.1 | B26: Backend nền tảng: xác thực JWT, phân quyền RBAC, tài khoản (UC01, UC22) | C26: Module auth | D26: TV1 | E26: =IFERROR(IF(INDEX('Thông tin'!$C$7:$C$9,MATCH(D26,'Thông tin'!$B$7:$B$9,0))="","",INDEX('Thông tin'!$C$7:$C$9,MATCH(D26,'Thông tin'!$B$7:$B$9,0))),"") -> Phạm Ngọc Trung | G26: 46328 | H26: 46334 | I26: =H26-G26+1 -> 7 | J26: 14 | K26: 3.2, 3.4 | L26: Chưa bắt đầu | M26: =IF(AND($G26<=M$3,$H26>=M$2),1,"") | N26: =IF(AND($G26<=N$3,$H26>=N$2),1,"") | O26: =IF(AND($G26<=O$3,$H26>=O$2),1,"") | P26: =IF(AND($G26<=P$3,$H26>=P$2),1,"") -> 1 | Q26: =IF(AND($G26<=Q$3,$H26>=Q$2),1,"") | R26: =IF(AND($G26<=R$3,$H26>=R$2),1,"") | S26: =IF(AND($G26<=S$3,$H26>=S$2),1,"") | T26: =IF(AND($G26<=T$3,$H26>=T$2),1,"") | ... Z26: =IF(AND($G26<=Z$3,$H26>=Z$2),1,"")
A27: 4.2 | B27: Danh mục: dịch vụ, bảng giá, KTV, khu vực, cấu hình (UC18, UC19, UC23) | C27: Module danh mục | D27: TV2 | E27: =IFERROR(IF(INDEX('Thông tin'!$C$7:$C$9,MATCH(D27,'Thông tin'!$B$7:$B$9,0))="","",INDEX('Thông tin'!$C$7:$C$9,MATCH(D27,'Thông tin'!$B$7:$B$9,0))),"") -> Trần Quốc Anh Hoàng | F27: TV1 | G27: 46335 | H27: 46341 | I27: =H27-G27+1 -> 7 | J27: 12 | K27: 4.1 | L27: Chưa bắt đầu | M27: =IF(AND($G27<=M$3,$H27>=M$2),1,"") | N27: =IF(AND($G27<=N$3,$H27>=N$2),1,"") | O27: =IF(AND($G27<=O$3,$H27>=O$2),1,"") | P27: =IF(AND($G27<=P$3,$H27>=P$2),1,"") | Q27: =IF(AND($G27<=Q$3,$H27>=Q$2),1,"") -> 1 | R27: =IF(AND($G27<=R$3,$H27>=R$2),1,"") | S27: =IF(AND($G27<=S$3,$H27>=S$2),1,"") | T27: =IF(AND($G27<=T$3,$H27>=T$2),1,"") | ... Z27: =IF(AND($G27<=Z$3,$H27>=Z$2),1,"")
A28: 4.3 | B28: Phiếu yêu cầu và máy trạng thái (UC04, UC06, UC07) | C28: Module phiếu | D28: TV1 | E28: =IFERROR(IF(INDEX('Thông tin'!$C$7:$C$9,MATCH(D28,'Thông tin'!$B$7:$B$9,0))="","",INDEX('Thông tin'!$C$7:$C$9,MATCH(D28,'Thông tin'!$B$7:$B$9,0))),"") -> Phạm Ngọc Trung | G28: 46335 | H28: 46348 | I28: =H28-G28+1 -> 14 | J28: 16 | K28: 4.1 | L28: Chưa bắt đầu | M28: =IF(AND($G28<=M$3,$H28>=M$2),1,"") | N28: =IF(AND($G28<=N$3,$H28>=N$2),1,"") | O28: =IF(AND($G28<=O$3,$H28>=O$2),1,"") | P28: =IF(AND($G28<=P$3,$H28>=P$2),1,"") | Q28: =IF(AND($G28<=Q$3,$H28>=Q$2),1,"") -> 1 | R28: =IF(AND($G28<=R$3,$H28>=R$2),1,"") -> 1 | S28: =IF(AND($G28<=S$3,$H28>=S$2),1,"") | T28: =IF(AND($G28<=T$3,$H28>=T$2),1,"") | ... Z28: =IF(AND($G28<=Z$3,$H28>=Z$2),1,"")
A29: 4.4 | B29: Điều phối và phân công KTV, BR-04 đến BR-06 (UC08, UC09) | C29: Module điều phối | D29: TV1 | E29: =IFERROR(IF(INDEX('Thông tin'!$C$7:$C$9,MATCH(D29,'Thông tin'!$B$7:$B$9,0))="","",INDEX('Thông tin'!$C$7:$C$9,MATCH(D29,'Thông tin'!$B$7:$B$9,0))),"") -> Phạm Ngọc Trung | G29: 46342 | H29: 46348 | I29: =H29-G29+1 -> 7 | J29: 12 | K29: 4.3 | L29: Chưa bắt đầu | M29: =IF(AND($G29<=M$3,$H29>=M$2),1,"") | N29: =IF(AND($G29<=N$3,$H29>=N$2),1,"") | O29: =IF(AND($G29<=O$3,$H29>=O$2),1,"") | P29: =IF(AND($G29<=P$3,$H29>=P$2),1,"") | Q29: =IF(AND($G29<=Q$3,$H29>=Q$2),1,"") | R29: =IF(AND($G29<=R$3,$H29>=R$2),1,"") -> 1 | S29: =IF(AND($G29<=S$3,$H29>=S$2),1,"") | T29: =IF(AND($G29<=T$3,$H29>=T$2),1,"") | ... Z29: =IF(AND($G29<=Z$3,$H29>=Z$2),1,"")
A30: 4.5 | B30: Báo giá và nghiệm thu (UC10, UC11, UC12, UC13) | C30: Module báo giá | D30: TV1 | E30: =IFERROR(IF(INDEX('Thông tin'!$C$7:$C$9,MATCH(D30,'Thông tin'!$B$7:$B$9,0))="","",INDEX('Thông tin'!$C$7:$C$9,MATCH(D30,'Thông tin'!$B$7:$B$9,0))),"") -> Phạm Ngọc Trung | G30: 46349 | H30: 46362 | I30: =H30-G30+1 -> 14 | J30: 12 | K30: 4.4 | L30: Chưa bắt đầu | M30: =IF(AND($G30<=M$3,$H30>=M$2),1,"") | N30: =IF(AND($G30<=N$3,$H30>=N$2),1,"") | O30: =IF(AND($G30<=O$3,$H30>=O$2),1,"") | P30: =IF(AND($G30<=P$3,$H30>=P$2),1,"") | Q30: =IF(AND($G30<=Q$3,$H30>=Q$2),1,"") | R30: =IF(AND($G30<=R$3,$H30>=R$2),1,"") | S30: =IF(AND($G30<=S$3,$H30>=S$2),1,"") -> 1 | T30: =IF(AND($G30<=T$3,$H30>=T$2),1,"") -> 1 | ... Z30: =IF(AND($G30<=Z$3,$H30>=Z$2),1,"")
A31: 4.6 | B31: Thanh toán tiền mặt, VietQR và đối soát (UC14) | C31: Module thanh toán | D31: TV2 | E31: =IFERROR(IF(INDEX('Thông tin'!$C$7:$C$9,MATCH(D31,'Thông tin'!$B$7:$B$9,0))="","",INDEX('Thông tin'!$C$7:$C$9,MATCH(D31,'Thông tin'!$B$7:$B$9,0))),"") -> Trần Quốc Anh Hoàng | F31: TV1 | G31: 46356 | H31: 46369 | I31: =H31-G31+1 -> 14 | J31: 8 | K31: 4.5 | L31: Chưa bắt đầu | M31: =IF(AND($G31<=M$3,$H31>=M$2),1,"") | N31: =IF(AND($G31<=N$3,$H31>=N$2),1,"") | O31: =IF(AND($G31<=O$3,$H31>=O$2),1,"") | P31: =IF(AND($G31<=P$3,$H31>=P$2),1,"") | Q31: =IF(AND($G31<=Q$3,$H31>=Q$2),1,"") | R31: =IF(AND($G31<=R$3,$H31>=R$2),1,"") | S31: =IF(AND($G31<=S$3,$H31>=S$2),1,"") | T31: =IF(AND($G31<=T$3,$H31>=T$2),1,"") -> 1 | ... Z31: =IF(AND($G31<=Z$3,$H31>=Z$2),1,"")
A32: 4.7 | B32: Tích hợp AI phân loại sự cố – Gemini API (UC05) | C32: Module AI | D32: TV1 | E32: =IFERROR(IF(INDEX('Thông tin'!$C$7:$C$9,MATCH(D32,'Thông tin'!$B$7:$B$9,0))="","",INDEX('Thông tin'!$C$7:$C$9,MATCH(D32,'Thông tin'!$B$7:$B$9,0))),"") -> Phạm Ngọc Trung | F32: TV3 | G32: 46342 | H32: 46355 | I32: =H32-G32+1 -> 14 | J32: 10 | K32: 3.6, 4.3 | L32: Chưa bắt đầu | M32: =IF(AND($G32<=M$3,$H32>=M$2),1,"") | N32: =IF(AND($G32<=N$3,$H32>=N$2),1,"") | O32: =IF(AND($G32<=O$3,$H32>=O$2),1,"") | P32: =IF(AND($G32<=P$3,$H32>=P$2),1,"") | Q32: =IF(AND($G32<=Q$3,$H32>=Q$2),1,"") | R32: =IF(AND($G32<=R$3,$H32>=R$2),1,"") -> 1 | S32: =IF(AND($G32<=S$3,$H32>=S$2),1,"") -> 1 | T32: =IF(AND($G32<=T$3,$H32>=T$2),1,"") | ... Z32: =IF(AND($G32<=Z$3,$H32>=Z$2),1,"")
A33: 4.8 | B33: Thông báo Telegram và email có hàng đợi (UC17) | C33: Module thông báo | D33: TV3 | E33: =IFERROR(IF(INDEX('Thông tin'!$C$7:$C$9,MATCH(D33,'Thông tin'!$B$7:$B$9,0))="","",INDEX('Thông tin'!$C$7:$C$9,MATCH(D33,'Thông tin'!$B$7:$B$9,0))),"") -> Nguyễn Văn Thu | F33: TV1 | G33: 46356 | H33: 46362 | I33: =H33-G33+1 -> 7 | J33: 8 | K33: 4.3 | L33: Chưa bắt đầu | M33: =IF(AND($G33<=M$3,$H33>=M$2),1,"") | N33: =IF(AND($G33<=N$3,$H33>=N$2),1,"") | O33: =IF(AND($G33<=O$3,$H33>=O$2),1,"") | P33: =IF(AND($G33<=P$3,$H33>=P$2),1,"") | Q33: =IF(AND($G33<=Q$3,$H33>=Q$2),1,"") | R33: =IF(AND($G33<=R$3,$H33>=R$2),1,"") | S33: =IF(AND($G33<=S$3,$H33>=S$2),1,"") | T33: =IF(AND($G33<=T$3,$H33>=T$2),1,"") -> 1 | ... Z33: =IF(AND($G33<=Z$3,$H33>=Z$2),1,"")
A34: 4.9 | B34: Bảo hành và đánh giá dịch vụ (UC15, UC16) | C34: Module hậu mãi | D34: TV3 | E34: =IFERROR(IF(INDEX('Thông tin'!$C$7:$C$9,MATCH(D34,'Thông tin'!$B$7:$B$9,0))="","",INDEX('Thông tin'!$C$7:$C$9,MATCH(D34,'Thông tin'!$B$7:$B$9,0))),"") -> Nguyễn Văn Thu | F34: TV1 | G34: 46363 | H34: 46376 | I34: =H34-G34+1 -> 14 | J34: 10 | K34: 4.6 | L34: Chưa bắt đầu | M34: =IF(AND($G34<=M$3,$H34>=M$2),1,"") | N34: =IF(AND($G34<=N$3,$H34>=N$2),1,"") | O34: =IF(AND($G34<=O$3,$H34>=O$2),1,"") | P34: =IF(AND($G34<=P$3,$H34>=P$2),1,"") | Q34: =IF(AND($G34<=Q$3,$H34>=Q$2),1,"") | R34: =IF(AND($G34<=R$3,$H34>=R$2),1,"") | S34: =IF(AND($G34<=S$3,$H34>=S$2),1,"") | T34: =IF(AND($G34<=T$3,$H34>=T$2),1,"") | ... Z34: =IF(AND($G34<=Z$3,$H34>=Z$2),1,"")
A35: 4.10 | B35: Giao diện khách hàng (UC02–UC07, UC11, UC13–UC16) | C35: Web khách hàng | D35: TV2 | E35: =IFERROR(IF(INDEX('Thông tin'!$C$7:$C$9,MATCH(D35,'Thông tin'!$B$7:$B$9,0))="","",INDEX('Thông tin'!$C$7:$C$9,MATCH(D35,'Thông tin'!$B$7:$B$9,0))),"") -> Trần Quốc Anh Hoàng | G35: 46335 | H35: 46369 | I35: =H35-G35+1 -> 35 | J35: 30 | K35: 3.5, 4.1 | L35: Chưa bắt đầu | M35: =IF(AND($G35<=M$3,$H35>=M$2),1,"") | N35: =IF(AND($G35<=N$3,$H35>=N$2),1,"") | O35: =IF(AND($G35<=O$3,$H35>=O$2),1,"") | P35: =IF(AND($G35<=P$3,$H35>=P$2),1,"") | Q35: =IF(AND($G35<=Q$3,$H35>=Q$2),1,"") -> 1 | R35: =IF(AND($G35<=R$3,$H35>=R$2),1,"") -> 1 | S35: =IF(AND($G35<=S$3,$H35>=S$2),1,"") -> 1 | T35: =IF(AND($G35<=T$3,$H35>=T$2),1,"") -> 1 | ... Z35: =IF(AND($G35<=Z$3,$H35>=Z$2),1,"")
A36: 4.11 | B36: Giao diện kỹ thuật viên trên điện thoại (UC09, UC10, UC12) | C36: Web KTV | D36: TV2 | E36: =IFERROR(IF(INDEX('Thông tin'!$C$7:$C$9,MATCH(D36,'Thông tin'!$B$7:$B$9,0))="","",INDEX('Thông tin'!$C$7:$C$9,MATCH(D36,'Thông tin'!$B$7:$B$9,0))),"") -> Trần Quốc Anh Hoàng | F36: TV3 | G36: 46349 | H36: 46376 | I36: =H36-G36+1 -> 28 | J36: 18 | K36: 4.4 | L36: Chưa bắt đầu | M36: =IF(AND($G36<=M$3,$H36>=M$2),1,"") | N36: =IF(AND($G36<=N$3,$H36>=N$2),1,"") | O36: =IF(AND($G36<=O$3,$H36>=O$2),1,"") | P36: =IF(AND($G36<=P$3,$H36>=P$2),1,"") | Q36: =IF(AND($G36<=Q$3,$H36>=Q$2),1,"") | R36: =IF(AND($G36<=R$3,$H36>=R$2),1,"") | S36: =IF(AND($G36<=S$3,$H36>=S$2),1,"") -> 1 | T36: =IF(AND($G36<=T$3,$H36>=T$2),1,"") -> 1 | ... Z36: =IF(AND($G36<=Z$3,$H36>=Z$2),1,"")
A37: 4.12 | B37: Giao diện điều phối viên và quản trị viên | C37: Web ĐPV, QTV | D37: TV2 | E37: =IFERROR(IF(INDEX('Thông tin'!$C$7:$C$9,MATCH(D37,'Thông tin'!$B$7:$B$9,0))="","",INDEX('Thông tin'!$C$7:$C$9,MATCH(D37,'Thông tin'!$B$7:$B$9,0))),"") -> Trần Quốc Anh Hoàng | F37: TV1 | G37: 46342 | H37: 46383 | I37: =H37-G37+1 -> 42 | J37: 22 | K37: 4.2 | L37: Chưa bắt đầu | M37: =IF(AND($G37<=M$3,$H37>=M$2),1,"") | N37: =IF(AND($G37<=N$3,$H37>=N$2),1,"") | O37: =IF(AND($G37<=O$3,$H37>=O$2),1,"") | P37: =IF(AND($G37<=P$3,$H37>=P$2),1,"") | Q37: =IF(AND($G37<=Q$3,$H37>=Q$2),1,"") | R37: =IF(AND($G37<=R$3,$H37>=R$2),1,"") -> 1 | S37: =IF(AND($G37<=S$3,$H37>=S$2),1,"") -> 1 | T37: =IF(AND($G37<=T$3,$H37>=T$2),1,"") -> 1 | ... Z37: =IF(AND($G37<=Z$3,$H37>=Z$2),1,"")
A38: 4.13 | B38: Báo cáo thống kê (UC21) | C38: Màn hình báo cáo | D38: TV3 | E38: =IFERROR(IF(INDEX('Thông tin'!$C$7:$C$9,MATCH(D38,'Thông tin'!$B$7:$B$9,0))="","",INDEX('Thông tin'!$C$7:$C$9,MATCH(D38,'Thông tin'!$B$7:$B$9,0))),"") -> Nguyễn Văn Thu | F38: TV2 | G38: 46370 | H38: 46383 | I38: =H38-G38+1 -> 14 | J38: 10 | K38: 4.6 | L38: Chưa bắt đầu | M38: =IF(AND($G38<=M$3,$H38>=M$2),1,"") | N38: =IF(AND($G38<=N$3,$H38>=N$2),1,"") | O38: =IF(AND($G38<=O$3,$H38>=O$2),1,"") | P38: =IF(AND($G38<=P$3,$H38>=P$2),1,"") | Q38: =IF(AND($G38<=Q$3,$H38>=Q$2),1,"") | R38: =IF(AND($G38<=R$3,$H38>=R$2),1,"") | S38: =IF(AND($G38<=S$3,$H38>=S$2),1,"") | T38: =IF(AND($G38<=T$3,$H38>=T$2),1,"") | ... Z38: =IF(AND($G38<=Z$3,$H38>=Z$2),1,"")
A39: 4.14 | B39: Quản lý linh kiện – mức Could (UC20) | C39: Module linh kiện | D39: TV3 | E39: =IFERROR(IF(INDEX('Thông tin'!$C$7:$C$9,MATCH(D39,'Thông tin'!$B$7:$B$9,0))="","",INDEX('Thông tin'!$C$7:$C$9,MATCH(D39,'Thông tin'!$B$7:$B$9,0))),"") -> Nguyễn Văn Thu | G39: 46377 | H39: 46383 | I39: =H39-G39+1 -> 7 | J39: 6 | K39: 4.2 | L39: Chưa bắt đầu | M39: =IF(AND($G39<=M$3,$H39>=M$2),1,"") | N39: =IF(AND($G39<=N$3,$H39>=N$2),1,"") | O39: =IF(AND($G39<=O$3,$H39>=O$2),1,"") | P39: =IF(AND($G39<=P$3,$H39>=P$2),1,"") | Q39: =IF(AND($G39<=Q$3,$H39>=Q$2),1,"") | R39: =IF(AND($G39<=R$3,$H39>=R$2),1,"") | S39: =IF(AND($G39<=S$3,$H39>=S$2),1,"") | T39: =IF(AND($G39<=T$3,$H39>=T$2),1,"") | ... Z39: =IF(AND($G39<=Z$3,$H39>=Z$2),1,"")
A40: 4.15 | B40: Chuẩn bị bản demo và báo cáo giữa kỳ | C40: Demo giữa kỳ (D8) | D40: TV1 | E40: =IFERROR(IF(INDEX('Thông tin'!$C$7:$C$9,MATCH(D40,'Thông tin'!$B$7:$B$9,0))="","",INDEX('Thông tin'!$C$7:$C$9,MATCH(D40,'Thông tin'!$B$7:$B$9,0))),"") -> Phạm Ngọc Trung | F40: TV2, TV3 | G40: 46349 | H40: 46355 | I40: =H40-G40+1 -> 7 | J40: 6 | K40: 4.3, 4.4 | L40: Chưa bắt đầu | M40: =IF(AND($G40<=M$3,$H40>=M$2),1,"") | N40: =IF(AND($G40<=N$3,$H40>=N$2),1,"") | O40: =IF(AND($G40<=O$3,$H40>=O$2),1,"") | P40: =IF(AND($G40<=P$3,$H40>=P$2),1,"") | Q40: =IF(AND($G40<=Q$3,$H40>=Q$2),1,"") | R40: =IF(AND($G40<=R$3,$H40>=R$2),1,"") | S40: =IF(AND($G40<=S$3,$H40>=S$2),1,"") -> 1 | T40: =IF(AND($G40<=T$3,$H40>=T$2),1,"") | ... Z40: =IF(AND($G40<=Z$3,$H40>=Z$2),1,"")
...

Sheet Phân công
B2: TỔNG HỢP PHÂN CÔNG THEO THÀNH VIÊN
B4: Mã | C4: Họ và tên | D4: Vai trò chính | E4: Số công việc phụ trách | F4: Tổng giờ ước lượng | G4: Tỷ lệ khối lượng
B5: ='Thông tin'!B7 -> TV1 | C5: =IF('Thông tin'!C7="","",'Thông tin'!C7) -> Phạm Ngọc Trung | D5: ='Thông tin'!E7 -> Nhóm trưởng – Backend, AI, DevOps | E5: =COUNTIF(WBS!$D$5:$D$53,B5) -> 17 | F5: =SUMIF(WBS!$D$5:$D$53,B5,WBS!$J$5:$J$53) -> 144 | G5: =IF(SUM($F$5:$F$7)=0,0,F5/SUM($F$5:$F$7)) -> 0.34285714
B6: ='Thông tin'!B8 -> TV2 | C6: =IF('Thông tin'!C8="","",'Thông tin'!C8) -> Trần Quốc Anh Hoàng | D6: ='Thông tin'!E8 -> Frontend, UI/UX | E6: =COUNTIF(WBS!$D$5:$D$53,B6) -> 9 | F6: =SUMIF(WBS!$D$5:$D$53,B6,WBS!$J$5:$J$53) -> 130 | G6: =IF(SUM($F$5:$F$7)=0,0,F6/SUM($F$5:$F$7)) -> 0.30952381
B7: ='Thông tin'!B9 -> TV3 | C7: =IF('Thông tin'!C9="","",'Thông tin'!C9) -> Nguyễn Văn Thu | D7: ='Thông tin'!E9 -> Phân tích nghiệp vụ, kiểm thử, tài liệu | E7: =COUNTIF(WBS!$D$5:$D$53,B7) -> 17 | F7: =SUMIF(WBS!$D$5:$D$53,B7,WBS!$J$5:$J$53) -> 146 | G7: =IF(SUM($F$5:$F$7)=0,0,F7/SUM($F$5:$F$7)) -> 0.34761905
B8: Tổng | E8: =SUM(E5:E7) -> 43 | F8: =SUM(F5:F7) -> 420 | G8: =SUM(G5:G7) -> 1
B11: KHỐI LƯỢNG THEO NHÓM CÔNG VIỆC (GIỜ)
B12: Mã | C12: Nhóm công việc | E12: TV1 | F12: TV2 | G12: TV3
B13: =WBS!A5 -> 1 | C13: =WBS!B5 -> Quản lý dự án | E13: =SUMIF(WBS!$D$6:$D$9,E$12,WBS!$J$6:$J$9) -> 23 | F13: =SUMIF(WBS!$D$6:$D$9,F$12,WBS!$J$6:$J$9) -> 0 | G13: =SUMIF(WBS!$D$6:$D$9,G$12,WBS!$J$6:$J$9) -> 0
B14: =WBS!A10 -> 2 | C14: =WBS!B10 -> Khảo sát và phân tích yêu cầu | E14: =SUMIF(WBS!$D$11:$D$16,E$12,WBS!$J$11:$J$16) -> 0 | F14: =SUMIF(WBS!$D$11:$D$16,F$12,WBS!$J$11:$J$16) -> 0 | G14: =SUMIF(WBS!$D$11:$D$16,G$12,WBS!$J$11:$J$16) -> 46
B15: =WBS!A17 -> 3 | C15: =WBS!B17 -> Thiết kế hệ thống (SAD) | E15: =SUMIF(WBS!$D$18:$D$24,E$12,WBS!$J$18:$J$24) -> 30 | F15: =SUMIF(WBS!$D$18:$D$24,F$12,WBS!$J$18:$J$24) -> 16 | G15: =SUMIF(WBS!$D$18:$D$24,G$12,WBS!$J$18:$J$24) -> 20
B16: =WBS!A25 -> 4 | C16: =WBS!B25 -> Hiện thực phần mềm | E16: =SUMIF(WBS!$D$26:$D$40,E$12,WBS!$J$26:$J$40) -> 70 | F16: =SUMIF(WBS!$D$26:$D$40,F$12,WBS!$J$26:$J$40) -> 90 | G16: =SUMIF(WBS!$D$26:$D$40,G$12,WBS!$J$26:$J$40) -> 34
B17: =WBS!A41 -> 5 | C17: =WBS!B41 -> Kiểm thử | E17: =SUMIF(WBS!$D$42:$D$46,E$12,WBS!$J$42:$J$46) -> 14 | F17: =SUMIF(WBS!$D$42:$D$46,F$12,WBS!$J$42:$J$46) -> 0 | G17: =SUMIF(WBS!$D$42:$D$46,G$12,WBS!$J$42:$J$46) -> 38
B18: =WBS!A47 -> 6 | C18: =WBS!B47 -> Triển khai và bàn giao | E18: =SUMIF(WBS!$D$48:$D$53,E$12,WBS!$J$48:$J$53) -> 7 | F18: =SUMIF(WBS!$D$48:$D$53,F$12,WBS!$J$48:$J$53) -> 24 | G18: =SUMIF(WBS!$D$48:$D$53,G$12,WBS!$J$48:$J$53) -> 8

Sheet Deliverables
B2: KẾT QUẢ BÀN GIAO (DELIVERABLES)
B4: Mã | C4: Kết quả bàn giao | D4: Mô tả | E4: Hạn nộp | F4: Phụ trách | G4: Gói WBS
B5: D1 | C5: Đề tài, phạm vi, deliverables | D5: Mục 1.2 và mục 7 của SRS | E5: 46313 | F5: TV1 | G5: 1.1
B6: D2 | C6: SRS sơ bộ | D6: Tài liệu đặc tả yêu cầu bản sơ bộ | E6: 46313 | F6: TV3 | G6: 2.3
B7: D3 | C7: WBS và kế hoạch | D7: File WBS này | E7: 46313 | F7: TV1 | G7: 1.1
B8: D4 | C8: Workspace Git | D8: Repo GitHub, quy ước nhánh, board công việc | E8: 46313 | F8: TV1 | G8: 1.2
B9: D5 | C9: SRS hoàn chỉnh | D9: Bổ sung khảo sát, đặc tả đủ 23 use case | E9: 46355 | F9: TV3 | G9: 2.6
B10: D6 | C10: Tài liệu phân tích thiết kế (SAD) | D10: Kiến trúc, UML, thiết kế API, wireframe | E10: 46355 | F10: TV3 | G10: 3.7
B11: D7 | C11: Lược đồ CSDL | D11: ERD và script migration | E11: 46355 | F11: TV1 | G11: 3.2
B12: D8 | C12: Bản demo giữa kỳ | D12: Tạo yêu cầu → phân công → báo giá → duyệt | E12: 46355 | F12: TV1 | G12: 4.15
B13: D9 | C13: Mã nguồn và hệ thống trực tuyến | D13: Repo GitHub, bản triển khai chính thức | E13: 46404 | F13: TV1 | G13: 6.2, 6.6
B14: D10 | C14: Kế hoạch và báo cáo kiểm thử | D14: Test case, kết quả, coverage, đánh giá AI | E14: 46404 | F14: TV3 | G14: 6.4
B15: D11 | C15: Hướng dẫn sử dụng | D15: Theo từng vai trò | E15: 46404 | F15: TV2 | G15: 6.3
B16: D12 | C16: Slide và demo bảo vệ | D16: Trình bày và demo trực tiếp | E16: 46404 | F16: TV2 | G16: 6.5
